Workbook
Name _List_Conformilty: [1]Data!$A$2:$A$6
Name act_name_sign1: #REF!
Name act_name_sign1: #REF!
Name act_name_sign1: #REF!
Name act_name_sign1: #REF!
Name act_name_sign2: #REF!
Name act_name_sign2: #REF!
Name act_name_sign2: #REF!
Name act_name_sign2: #REF!
Name act_name_sign3: #REF!
Name act_name_sign3: #REF!
Name act_name_sign3: #REF!
Name act_name_sign3: #REF!
Name act_name_sign4: #REF!
Name act_name_sign4: #REF!
Name act_name_sign4: #REF!
Name act_name_sign4: #REF!
Name azer: #REF!
Name azer: #REF!
Name azer: #REF!
Name Cotation: [2]Legend!$B$15:$B$20
Name D: #REF!
Name D: #REF!
Name D: #REF!
Name dggt: #REF!
Name dggt: #REF!
Name dggt: #REF!
Name edg: #REF!
Name edg: #REF!
Name edg: #REF!
Name eds: #REF!
Name eds: #REF!
Name eds: #REF!
Name ESC: '[3]Clauses et Reponse '!#REF!
Name ESC: '[3]Clauses et Reponse '!#REF!
Name ESC: '[3]Clauses et Reponse '!#REF!
Name fcvgt: #REF!
Name fcvgt: #REF!
Name fcvgt: #REF!
Name g: #REF!
Name g: #REF!
Name g: #REF!
Name g: #REF!
Name MATRICE_COUVERTURE_DES_EXIGENCES: '[3]Clauses et Reponse '!#REF!
Name MATRICE_COUVERTURE_DES_EXIGENCES: '[3]Clauses et Reponse '!#REF!
Name MATRICE_COUVERTURE_DES_EXIGENCES: '[3]Clauses et Reponse '!#REF!
Name MATRICE_COUVERTURE_DES_EXIGENCES: '[3]Clauses et Reponse '!#REF!
Name P_APPLICATION_DATE: #REF!
Name P_APPLICATION_DATE: #REF!
Name P_APPLICATION_DATE: #REF!
Name P_APPLICATION_DATE: #REF!
Name P_REVISION: #REF!
Name P_REVISION: #REF!
Name P_REVISION: #REF!
Name P_REVISION: #REF!
Name P_REVISION_COMMENT: #REF!
Name P_REVISION_COMMENT: #REF!
Name P_REVISION_COMMENT: #REF!
Name P_REVISION_COMMENT: #REF!
Name q: #REF!

Sheet En-tête - 1st Page
B3: Nom de l'entité | D3: SWX/EHSE/EEEM/EEWE/CIWE/DIWE/HD2C
B4: Référence | D4: A créer | G4: Version | I4: V1
B5: Date d'application | G5: Date d'échéance
B6: Confidentialité | D6: Usage externe
B7: Exigences sur le développement
B8: DM12F
B9: Development guidelines
B10: OBJET:
B11: L'objectif de ce document est de spécifier les exigences sur le processus de développement spécifiques. Il est demandé d'intégrer ces demandes dans l'offre de la consultation.
B12: This document is to specify specifics requirements about of the development process. These requirement shall be quoted in the RFQ offer by the supplier.
B14: MODIFICATIONS
B15: Indice de révision | C15: Date | D15: Auteur | E15: Nature des modifications
B16: V1 | C16: 46014 | D16: A.HAZEBROUCQ | E16: Création / Initial release
B23: CYCLE DE SIGNATURE
D24: Rédacteur | E24: Vérificateur | H24: Approbateur
B25: Nom | E25: P.GARCIA | H25: F. VELTZ
B26: Date
B27: SIGNATURES ELECTRONIQUES SOUS OUTIL DE GESTION DOCUMENTAIRE
B29: Template : | C29: 02017_17_00476 | H29: Plan type QMS_ASQ07_0133/ V1

Sheet Requirements
A1: SUPPLIER NAME | B1: Exigences / Requirements | G1: Matrice de conformité / Conformity Matrix
A2: DESIGNATION | B2: REFERENCE | C2: ID | D2: DOCUMENT | E2: Exigences / Requirements | G2: Conformité Conformity | H2: Remarques Fournisseur Supplier comments | I2: Statut Status STELLANTIS | J2: Commentaires STELLANTIS Comments
A3: Planning Timing Plan | B3: DEV_REQ_DM12F.001 | C3: 0 | D3: Timing plan | E3: Le planning du développement du fournisseur respecte les jalons listés dans l'onglet "Timing_Plan" Supplier's timing plan shall comply with STELLANTIS milestones listed in "Timing_Plan" sheet | G3: OK | I3: EN ATTENTE
A4: Evolution des spécifications Specifications update | B4: DEV_REQ_DM12F.002 | C4: 0 | D4: Supplier | E4: 3 livraisons de mise au point des TS fonctionnelles et IHM sont à intégrer dans l’offre de base pour la phase de développement. Cela n'inclut pas la livraison de regularisatio nau choix fournisseur. 3 updates of Functional & HMI TS packages have to be included in the basis offer for the development stage. that doesn't include delivery package at supllier award. | G4: OK | I4: EN ATTENTE
A5: Global Warming Potential | B5: DEV_REQ_DM12F.003 | C5: 0 | D5: Supplier | E5: Le fournisseur s'engage à transmettre le document Part_GWP et s'engage sur la cible du projet avant le choix fournisseur. Une mise à jour sera communiquée lors des mensuelles Achats. The supplier commits to forward the Part_GWP document and to commit to the target of the project before the supplier choice. This document will be upgraded at each Purchase monthly meeting. - As announced in STELLANTIS Dare Forward strategic plan, Stellantis committed to be carbon net zero by 2038 and to reduce by 2 its global Warming Potential (GWP) emissions in 2030 compared to 2021. - STELLANTIS took the commitment to reduce its supply chain carbon footprint (scope 3 upstream) by 40% in 2030 (vs 2021 for BEVs purchased parts). - This decrease shall result from both the improvements of your production (scope 1 & 2) and your supply chain (scope 3 upstream), thanks to mass lightening, more efficient process, greener energy, greener materials. GWP targets are defined at the SOP (Start Of Production) of the project and in 2030. - In addition to provide your more robust assessment for the SOP & 2030, you will complete the GWP form in order to give the main hotspots per components, on scope 1, 2 & 3. - GWP target = 42,11kg CO2eq/part - To take into consideration local specificities, an assessment per production location is required, if any. Documents : "STELLANTIS_Part_GWP form for supplier" | G5: OK | I5: EN ATTENTE
A6: Recettes SW & HW HW & SW acceptance delivery meetings | B6: DEV_REQ_DM12F.004 | C6: 0 | D6: QGATE | E6: Le fournisseur s’engage à se conformer aux règles définies dans le document QGATE_Template.xlsx, conformément au processus défini par STELLANTIS. En particulier, le fournisseur doit s’engager à : - Renseigner et fournir le document QGate à la date définie préalablement à chaque « recette ». - Fournir tous les documents dûs qui sont listés dans la QGate, avec un contenu conforme à l’exigence, - Respecter les critères d’acceptation des « recettes ». The supplier commits to apply the QGATE_Template.xlsx document, according to STELLANTIS process. In particular, the supplier shall commits : - To provide the QGate document at the due date, before each sample delivery (“recette” sessions), - To provide all the due documents which are listed in the Qgate document, with a correct content, - To respect the acceptance criteria of sample deliveries (during "Acceptance Review"). | G6: OK | I6: EN ATTENTE
B7: DEV_REQ_DM12F.005 | C7: 0 | D7: Supplier | E7: Le fournisseur intègre dans l'offre de base de la RFQ le coût des pièces prototypes requises pour les recettes et validations des équipes Développement et de Validation. La présente exigence couvre les besoins suivants : The supplier must include in the initial budget (i.e. during the RFQ stage) the cost of samples required by the Development & Validation Teams for acceptance reviews. The following samples must be considered : - Acceptance review Nr1 : 2 samples - Acceptance review Nr2 : 3 samples - Acceptance review Nr3 : 3 sample - Acceptance review Nr4 : 4 sample - Acceptance review Nr5 : 2 sample - Acceptance review Nr6 : 3 sample - Off-tools part design review : 1 sample | G7: OK | H7: For this project, no Cluster application. Only RSE and CID | I7: EN ATTENTE
B8: DEV_REQ_DM12F.006 | C8: 0 | D8: Supplier | E8: Le boitier test box permet : - A partir d'un ordinateur d'afficher une image sur le DISPLAY MODULE via une prise HDMI - D'afficher sur l'écran de l'ordinateur les coordonnées tactiles envoyé par le DISPLAY MODULE - D'afficher le contenu des trames sur l'écran de l'ordinateur - D'avoir un rendu dynamique sur l'écran d'ordinateur des coordonnées tactiles envoyé par le DISPLAY MODULE - D'effectuer en enregistrement des trames sur le réseau (Via une commande stop & start par bouton poussoir) The Test BOX allows: - To display a picture from the computer screen to the DISPLAY MODULE via a HDMI socket. - To display on the computer screen the tactile coordinates sent by the DISPLAY MODULE - To display the frames contents on the computer screen. - To display, on the computer screen, a dynamic representation of the tactile coordinates sent by the DISPLAY MODULE - To perform a network frames recording (Via a press button Stop & start) | G8: OK
B9: DEV_REQ_DM12F.007 | C9: 0 | D9: Supplier | E9: Le fournisseur s'engage à fournir les paramètres de timing vidéos à la date définie dans l'onglet "Timing plan". The supplier shall commit to fill-in the video timing table, respecting the due date which is specified in the "Timing plan" sheet. | G9: OK | I9: EN ATTENTE
B10: DEV_REQ_DM12F.008 | C10: 0 | D10: Supplier | E10: Le fournisseur intègre dans l'offre de base de la RFQ le coût (prix des pièces + frais d'expédition) des pièces prototypes requises pour développer le contrôleur d'écran (appelé head unit). Le fournisseur s'engage à livrer les pièces suivantes aux fournisseurs du système head unit : The supplier must include in the initial budget (i.e. during the RFQ stage) the cost of samples (part price + shipment cost) which are necessary to develop the display controller (named head unit). The supplier shall commit to deliver the following samples to the head-unit suppliers : - B1 maturity : * 1 sample to be delivered to the Hardware supplier * Delivery date : sheet Timing Plan * Delivery place : Europe - B2 maturity : * 4 samples to be delivered to the Hardware supplier * Delivery date : sheet Timing Plan * Delivery place : Europe - B2 maturity : * 10 samples to be delivered to the Software supplier * Delivery date : sheet Timing Plan * Delivery place : India | G10: OK | I10: EN ATTENTE
B11: DEV_REQ_DM12F.009 | C11: 0 | D11: Supplier | E11: Le fournisseur s'engage à participer à des réunions de travail périodiques en audioconférence, ainsi qu'aux 2 séances en présentiel avec les fournisseurs du système head-unit : The supplier shall commit to attend regular conference calls, and to attend the following workshops (face to face) with the head unit suppliers : - 1st Workshop : * Aim of the meeting : Development kick-off with the supplier of the Head-Unit's Hardware * Target date : beginning of xxxx * Maximum duration : 1 week * Location : Europe - 2nd Workshop : * Aim of the meeting : Technical review & initial test of the cluster's sample with the supplier of the Head-Unit's Hardware * Target date : xxxx * Maximum duration : 2 weeks * Location : Europe | G11: OK | H11: Europe or USA? | I11: EN ATTENTE
B12: DEV_REQ_DM12F.010 | C12: 0 | D12: Supplier | E12: Le fournisseur s'engage à participer à des réunions tripartite avec les fournisseurs rang 2 et STELLANTIS tant que nécessaire. The supplier shall commit to attend tripartite meeting withTIER2 supplier and STELLANTIS as long as necessary | G12: OK | I12: EN ATTENTE
B13: DEV_REQ_DM12F.011 | C13: 0 | D13: Supplier | E13: Le fournisseur intègre dans l'offre de base de la RFQ le coût des pièces prototypes requises pour la validation Style et Ergonomie. La présente exigence couvre les besoins suivants : - une maquette de Style du combiné complet, incluant : la vitre (avec ses traitements), le capot, le jonc chromé, le support, le logement pour le module d'éclairage d'ambiance. L'aspect de ce prototype doit être représentatif du produit de série. - 3 maquettes pour la mise au point d'aspect de la vitre, incluant : la vitre (intégrant plusieurs variantes de traitements, couleurs...), le capot, le hardware et l'afficheur, la pièce support. Seul l'aspect de la cover-glass et le rendu de l'afficheur doivent être représentatifs du produit de série. - 1 maquette pour validation IHM avec une test box The supplier must include in the initial budget (i.e. during the RFQ stage) the cost of samples required Styling & Ergonomics needs. The following samples must be considered : - Styling mock-up of the cluster including : coverglass (including AR coating & LCF), cover, chrome ring, support part, slot for the ambient lighting module. The appearance of this mock-up must be representative of the final one - 3 samples for coverglass' appearance validation including : coverglass (including various coating, process or colours), cover, HW & display, support part. Only the appearance of the coverglass and the display rendering must be representative of the final product. - 1 sample for HMI validation with a Test box | G13: OK | I13: EN ATTENTE
B14: DEV_REQ_DM12F.012 | C14: 0 | D14: Supplier | E14: Le nombre de pièces pour les besoins prototypes seront confirmés en developpement. Pour information on peut estimer à environ 100 prototypes pour les phases B1, B2, B3 The quantity of validation displays will confirm in developpement. For information we can estimate at 100 prototypes for the steps B1, B2, B3. | G14: OK | H14: not in the budget for free sample. | I14: EN ATTENTE
B15: DEV_REQ_DM12F.013 | C15: 0 | D15: xxxx | E15: Le document "technical answer supplier" est renseigné et mis à jour à chaque livraison de dossier technique à STELLANTIS. "The technical answer supplier" document is filled in and updated at each technical package release to STELLANTIS. | G15: OK | I15: EN ATTENTE
A16: Stade DFNu DFNu stage | B16: DEV_REQ_DM12F.014 | C16: 0 | D16: Supplier | E16: SYNC 2 3D illustrant les limites de pièces définies coherente des pieces composants l'organe. Position des embases cinematique (débattement en fonctionnement + cinématique de montage), hypothèses de fixation avec les interface critiques figées (basées sur définition interfaces disponible). Angle de demoulages inclu dans la definition du fournisseur. Definition avec maillage. SYNC2 The supplier shall provide a CAD Data with the delimitation of the part compliant of inner parts. Connector position, Kinematic (In working and assembly Kenematic). Fixing Hypothesys with the critical interface frozen based on the available fixation points. The supplier delivry includes the demolding angle. Definition with meshing. | G16: OK | I16: EN ATTENTE
B17: DEV_REQ_DM12F.015 | C17: 0 | D17: Supplier | E17: SYNC 3 Le 3D du fournisseur illustre la conception interne de l'organe. Définition fournisseur a 80%. Processe des pieces acquis, plan 2D avec convergence CTF encours. Definition avec maillage. SYNC 3 The CAD Dat supplier illustrates the inner conception of the part. Supplier definition clarified at 80%. Part process defined. 2D drawing with CTF convergence on going. Definition with meshing. | G17: OK | I17: EN ATTENTE
B18: DEV_REQ_DM12F.016 | C18: 0 | E18: SYNC 4 Le 3D du fournisseur illustrant la conception complete de l'organe (100%)(avec les composants internes) et représentatif des dernières données d'entrée STELLANTIS reçues (modèle Style, interfaces & environnement Planche de Bord...).Approbation style SYNC 4 The CAD Data supplier illustrate the full design of the part. (100%) (including internal parts) according to STELLANTIS last entry data (styling volume, mechanical interfaces with Instrument Panel...). Style Approval | G18: OK | I18: EN ATTENTE
B19: DEV_REQ_DM12F.017 | C19: 0 | D19: Supplier | E19: SYNC 5 Le 3D du fournisseur avec robustesse et convergence realisée. Finalisation pour Top RO. SYNC 5 CAD Data supplier with robusteness and convergence completed. Completion TKO. | G19: OK | I19: EN ATTENTE
A20: Ressources fournisseur Supplier resources | B20: DEV_REQ_DM12F.018 | C20: 0 | D20: Supplier | E20: L'organisation fournisseur doit être définie de sorte que : - les membres en interface avec STELLANTIS durant la phase de développement soient situés à proximité des centres R&D de STELLANTIS - les membres intervenant en Usine Terminale durant la phase d'industrialisation soient situés à proximité des sites de production STELLANTIS ou DPCA (selon le cas) The supplier's project team shall be located according to STELLANTIS footprint : - Supplier's members supporting STELLANTIS during the development stage, shall be located close to the STELLANTIS development plants D&D. - Supplier's members supporting STELLANTIS or DPCA in STELLANTIS or DPCA production's plants during the industrialization stage, shall be located close to STELLANTIS or DPCA factories | G20: OK | I20: EN ATTENTE
A21: Maturity delivery | B21: DEV_REQ_DM12F.019 | C21: 0 | D21: ='En-tête - 1st Page'!D4 -> A créer | E21: Le fournisseur doit respecter les contenus décrit dans l'onglet "Maturity Requirement" pour chaque livraison du document "Development_Requirements". The supplier must respect the content describt in the sheet "Maturity Requirement" of each delivery of document "Development_Requirements". | G21: OK | I21: EN ATTENTE
B22: DEV_REQ_DM12F.020 | C22: 0 | D22: Supplier | E22: Lors de la phase de montée en cadence (Dés les VRS...) le fichier de pastillage (tracabilité des versions HW / SW / Mécanique / mise au point d'outillages...) inclut le suivi des pieces primaires. During the ramp up (From the VRS…) the modification tracability includes also tracability of the primary parts (tracability of the versions HW / SW / Mechanic / Tooling tuning...). | G22: OK | I22: EN ATTENTE
A23: APQP | B23: DEV_REQ_DM12F.021 | C23: 0 | D23: 01276_15_00086 | E23: Le fournisseur s'engage, lors de la RFQ, le respect des livrables APQP demandés dans la grille APQP. During the RFQ, the supplier gives a commitment on the APQP deliverable requested in the APQP grill. | G23: OK | I23: EN ATTENTE
B24: DEV_REQ_DM12F.022 | C24: 0 | D24: 01301_15_01026 | E24: Le fournisseur s'engage, lors de la RFQ, le respect des livrables APQP demandés dans le document Generic EE deliverables. During the RFQ, the supplier gives a commitment on the APQP deliverable requested in the Generic EE deliverable document. | G24: OK | I24: EN ATTENTE
B25: DEV_REQ_DM12F.023 | C25: 0 | D25: Supplier | E25: Le fournisseur s'engage à faire respecter les mêmes standands qualités exigés par STELLANTIS a ses fournisseurs rang N. The supplier commits himself enforcing same the quality standards, required by STELLANTIS,to his suppliers rank N. | G25: OK | I25: EN ATTENTE
A26: VALIDATION PLAN | B26: DEV_REQ_DM12F.024 | C26: 0 | D26: 01843_20_00575 | E26: Le plan de validation doit être completé pendant la phase RFQ. The validation plan must be filled in during the RFQ phase. | G26: OK | I26: EN ATTENTE
B27: DEV_REQ_DM12F.025 | C27: 0 | D27: Supplier | E27: Les validations (EMC et environnemental) sont réalisées avec le Telltales box et les écrans en position. Le telltales box et les écrans sont alimentés lorsque l'essai le demande. Des mesures optiques avant et après les essais sont réalisées. The validations (EMC and environnemental) are realized with the telltales box and displays included. The telltales box and the displays are powered when the test ask it. The optical measurements before and after the test are performed. | G27: N/A | H27: no TT box in this project | I27: EN ATTENTE
B28: DEV_REQ_DM12F.026 | C28: 0 | D28: Supplier | E28: Le fournisseur réalise les mesures photometriques des écrans et des témoins assemblés dans leur mécanique. Ces mesures sont réalisées en phase DV et PV. The supplier performes the displays and telltales optical measurements integrated in the assembly part. These measurements are realize in DV and PV phase. | G28: N/A | H28: no TT box in this project | I28: EN ATTENTE
A29: PCP | B29: DEV_REQ_DM12F.027 | C29: 0 | D29: CTF RCM | E29: Le fournisseur s’engage à répondre au document CTF_RCM pendant la phase de developpement. Le document communiqué en RFQ est générique et n'est pas exhaustif. Tout au long du developpment, les CTF fonctionnelles doivent être mises à jour en fonction de la ST GENERIQUE. Les CTF mecaniques doivent inclure les pieces primaires. The supplier is committed to answer the Parts Inspection Standard CTF_RCM during the development phase. The document provided in RFQ is generic and not exhautive.Throughout development, the functional CTFs must be updated accordingthe GENERIC ST. The Mechanical CTFs must include the primary parts. | G29: OK | I29: EN ATTENTE
B30: DEV_REQ_DM12F.028 | C30: 0 | D30: Supplier | E30: Durant la RFQ, Le fournisseur livre la liste des moyens de tests couvrant a minimal les demandes du PCP generique. During the RFQ, The supplier provides the test means list meeting at least, the requests in the PCP. | G30: OK | I30: EN ATTENTE
A31: PED /PMR | B31: DEV_REQ_DM12F.029 | C31: 0 | D31: Supplier | E31: Le fournisseur s’engage à répondre le PED et transmet leur PED pendant la phase RFQ. The supplier commits to answer the PPH and transmit their PPH during the RFQ phase. | G31: OK | I31: EN ATTENTE
B32: DEV_REQ_DM12F.030 | C32: 0 | D32: Supplier | E32: Le fournisseur s'engage à répondre au PMR et transmet leur PMR pendant la phase RFQ. The supplier commits to answer the RISK LIST and transmit their RISK LIST during the RFQ phase. | G32: OK | I32: EN ATTENTE
A33: Durabilité Durability | B33: DEV_REQ_DM12F.031 | C33: 0 | D33: Supplier | E33: Le fournisseur s’engage à appliquer le démarche durabilité, à renseigner le tableau pendant la phase RFQ et a prendre en compte dans l'offre economique, les essais suplementaires dans le cadre de la démarche durabilité. The supplier commits to apply the durability process, to fill in the durability table during the RFQ phase and take into account in the offer, the extra tests needed in the durability process. | G33: OK | I33: EN ATTENTE
B34: DEV_REQ_DM12F.032 | C34: 0 | D34: Supplier | E34: The fournisseur Rang1 réalise les DFMEA de la pièce assemblée en tenant en compte les pieces primaires. The TIER1 realizes the DFMEA of the assembly part in taking into account the primary parts. | G34: OK | I34: EN ATTENTE
A35: INDUSTRIALIZATION | B35: DEV_REQ_DM12F.033 | E35: En RFQ le fournisseur rang 1 communique la list et la localisation des fournisseurs des composants clé. In RFQ, the TIER 1 provides bidlist and localization of key component suppliers | G35: OK | I35: EN ATTENTE
B36: DEV_REQ_DM12F.034 | C36: 0 | D36: Supplier | E36: Un fournisseur de rang 1 est complétement responsable de la qualité des pièces livrées à STELLANTIS (ensemble et sous ensemble). Quel que soit l’origine de la défaillance, le fournisseur de rang 1 est tenu pour responsable de celle-ci. Il se verra notifié et impacté comme tel et devra gérer les actions de mise en conformité. En conséquence, afin d’éviter au fournisseur de rang 1 de souffrir d'éventuelles défaillances d’un fournisseur de rang 2 (y compris les fournisseurs proposés acceptés par STELLANTIS GROUPE), STELLANTIS GROUPE suggère ceux-ci d’avoir une étroite collaboration avec les fournisseurs de rang 2 afin d’identifier toutes les actions nécessaires (Vérifications en entrée, attention particulière à apporter sur la pièce, contrôle sur la ligne de production…) qui doivent être prises afin de protéger STELLANTIS GROUPE contre des livraisons de pièces non conforme. A Tier 1 supplier is fully responsible for the quality of the parts delivered to STELLANTIS (part and sub assembled modules). Regardless of the cause of the failure, Tier 1 supplier is held responsible for it. It will be notified and impacted as such and will have to manage compliance actions. Consequently, in order to prevent the Tier 1 supplier from suffering from any failures of the Tier 2 supplier (including STELLANTIS directed buy supplier), STELLANTIS GROUPE suggests that they work closely with the Tier 2 suppliers to identify all the necessary actions (Input checks, special attention to be paid to the part, control on the production line, etc.) that must be taken to protect STELLANTIS GROUPE against non-conforming part deliveries. | G36: OK | I36: EN ATTENTE
B37: DEV_REQ_DM12F.035 | C37: 0 | D37: Supplier | E37: Apres assemblage, le rang 1 est responsable des exigences qualités d'aspects (poussière, rayure …) du produit fini, y compris pour les pieces primaires. (Ecrans, Telltales box ..). Le chiffrage de la RFQ inclut les moyens de controles sur la ligne de production. After assembling, the TIER1, is responsable for the quality aspect requierments (Dust, scratch...) of the final product included the pimary parts. (Display, Telltales box ...) The RFQ quotation includes the monitoring means in the production line. | G37: OK | I37: EN ATTENTE
B38: DEV_REQ_DM12F.036 | C38: 0 | D38: Supplier | E38: Le chiffrage de la RFQ inclut les moyens pour alimenter les pieces primaires afin de réaliser les essais prendant la phase de developpement ainsi que les moyens pour alimenter les pieces primaires sur la ligne de production. The RFQ quotation includes the means to power the primary part in order to realize the developpment tests and also the means to power the primary parts on the production line. | G38: OK | I38: EN ATTENTE
B39: DEV_REQ_DM12F.037 | C39: 0 | D39: Supplier | E39: Le fournisseur rang1 traite directement avec le fournisseur rang 2, les quantités et les plannings des pieces primaires pour la réalisation des validations, des VRS... de la montée en cadence... The TIER1 deals with the TIER1 the quatity and the schedule for the primary parts needed for the validations, VRS... the ramp up... Take into account in the schedule, the delivery timing and the customs timing.... | G39: OK | I39: EN ATTENTE
B40: DEV_REQ_DM12F.038 | C40: 0 | D40: Supplier | E40: Si une action de modernisation de pièce est nécessaire suite à une pièce primaire défectueuse ou a une défaillance au niveau de la pièce assemblée, le rang 1 est responsable de la gestion de stocks de pièces. If a modernization action is needed, because of faulty primary part or issue on the assembly part, the TIER1 is liable to manage the safety stock of parts | G40: OK | I40: EN ATTENTE
...

Sheet TIMING PLAN PDP
B2: ='En-tête - 1st Page'!B9:J9 -> Development guidelines
B3: Milestones or Activities | E3: Expected date | F3: Tianma (Same as DM12.3F2) | G3: STELLANTIS VALIDATION | I3: STELLANTIS COMMENTS
B4: R F Q | C4: Start
C5: Supplier answer | G5: Not Rated
C6: Supplier presentation | G6: Not Rated
C7: Addendum RFQ | G7: Not Rated
C8: Supplier answer Addendum (last release) | G8: Not Rated
C9: Supplier presentation Addendum | G9: Not Rated
C10: Supplier answer Addendum (last release) | G10: Not Rated
C11: Start of development / Kick Off Meeting | F11: 46230 | G11: Not Rated
B12: SYNC2 | C12: Stellantis Fct 3D model CLASS C (DNS) for SYNC 2 | F12: 46223 | G12: Not Rated
C13: SYNC 2 supplier delivery | E13: Supplier expected date | F13: 46272 | G13: Not Rated
C14: Meshing model Rel.2 (Radioss, LS DYNA, Nastran) | E14: DFNub supplier delivery + 3 weeks | F14: 46293 | G14: Not Rated
B15: A0 | C15: Low layer tests repport and conformity justication file | E15: B1 delivery-4 weeks (Documents) | F15: 46363 | G15: Not Rated
B16: B1 | C16: Data freeze for B1 samples | D16: STLA TFT technical approval (For TFT Kick off) | E16: Supplier expected date | F16: 46258 | G16: Not Rated
D17: Technical specification freeze | E17: Supplier expected date | F17: 46286
D18: Optical review | E18: Supplier expected date | F18: 46314 | G18: Not Rated
D19: Validation SW tool Availability | E19: Supplier expected date | F19: 46314 | G19: Not Rated
D20: HW review | E20: Supplier expected date | F20: 46314 | G20: Not Rated
C21: Description of Samples Maturity | E21: Expect a description | F21: HW1,SW1, 12.3" TFT, CNC mechanical part | G21: Not Rated
C22: B1 Q Gate documents + Full validation report | E22: 46363 | F22: 46384 | G22: Not Rated
C23: B1 delivery part + Acceptance review | E23: 46370 | F23: 46391 | G23: Not Rated
B24: SYNC 3 | C24: Stellantis Fct 3D model CLASS B for SYNC 3 | E24: 46370 | F24: 46300 | G24: NA
C25: SYNC 3 Supplier delivery | E25: Meshing - 3 weeks | F25: 46328 | G25: Not Rated
C26: Meshing model Rel.2 (Radioss, LS DYNA, Nastran) | E26: Date projet DFNUc Supplier delivery +3 week | G26: Not Rated
C27: Officialisation DFNu C CAD data- DRR | E27: Date projet | G27: Not Rated
B28: B2 | C28: Data freeze for B2 samples | D28: Technical specification freeze | E28: Supplier expected date | G28: Not Rated
D29: Freeze of the Bug fixing list | E29: Supplier expected date | G29: Not Rated
D30: Optical review | E30: Supplier expected date | G30: Not Rated
D31: Mechanical review | E31: Supplier expected date | G31: Not Rated
D32: Validation SW tool Availability | E32: Supplier expected date | G32: Not Rated
D33: HW review | E33: Supplier expected date | G33: Not Rated
C34: Description of Samples Maturity | E34: Expect a description | F34: HW2, SW2, 12.3" TFT, CNC parts | G34: Not Rated
C35: B2 Q Gate documents + Full validation report | E35: B2 Acceptance review - 1week | F35: 46440 | G35: Not Rated
C36: B2 delivery part + Acceptance review | E36: 46447 | F36: 46447 | G36: Not Rated
C37: End of B2 EMC validation | F37: 46425 | G37: Not Rated
C38: Delivery IVP parts | E38: B2 Acceptance review + 3 weeks | F38: 46468 | G38: Not Rated
B39: SYNC 4 | C39: Stellantis Fct 3D CLASS A for SYNC 4 | E39: Date | F39: 46356 | G39: Not Rated
C40: SYNC 4 Supplier delivery | E40: Supplier expected date | F40: 46384 | G40: Not Rated
B41: B3 | C41: Data freeze for B3 samples | D41: Technical specification freeze | E41: Supplier expected date | G41: Not Rated
...

Sheet Maturity Requirements Disp (FR)
B2: Maturité de l'organe pour chaque stade du projet
D4: Dénomination Maturité | E4: VEHICULE: A0 ORGANE: Vf-2-ProtoB | F4: VEHICULE: B1 ORGANE: Vf-1-ProtoB | G4: VEHICULE: B2 ORGANE: Vf-ProtoB ou C | H4: B3 | I4: C4 | J4: VEHICULE: C5 ORGANE: Vc2-ProtoC | K4: D5
D5: Utilisation | E5: TU | F5: TU / Chaine organique | G5: TI | H5: Mulets
D6: Jalons | E6: Validation Définition Préliminaire | F6: Validation Définition | I6: Accord pour livrer IOD | K6: Accord pour livraison IPD
B7: Mécanique | C7: Etat physique de la pièce | E7: Sans piece | F7: PROTOTYPE | G7: PROTOTYPE | H7: PROTOTYPE | I7: IOD (avec une première mise au point) | J7: IOD Mis au point (MAP terminée) (1 boucle minimum) | K7: IPD Conforme Validation du process : Quelques soient les résultats des phases précédentes, tous les essais doivent être refaits et conformes pour D5 (tactile, physico chimique et mécanique) .
E8: Encombrement : _ | F8: Encombrement : Issu du premier concept mecanique du fournisseur | G8: Encombrement : Issu de dernier plan de forme | H8: Encombrement : Issu du dernier plan de forme. (Pour les pieces devant etre montée sur véhicule, les fixations doivent permettre cing montages demontages)
E9: Connectique : _ | F9: Embase : représentative | G9: Embase : représentative | H9: Embase : représentative | I9: Embase : représentative
F10: Première version du TFT cible | G10: Tactile : Conforme à la STD/STO. | H10: Afficheur (TFT representatif pas forcement issu des lignes séries) | I10: Afficheur (TFT issu de la ligne de la ligne de production série)
G11: Choix des matériaux figé. Conception mécanique figée.
C12: Niveau de Conformité / Etat des livrables attendus
B13: Logiciel | C13: Niveau de l'implémenté | D13: Applicatif fonctionnel | E13: 30% des fonctions implémentées et exploitables dont au minimum : - 100% Couche basse LVDS - Afficher une image | F13: Pour cette livraison, il est demandé au FOURNISSEUR d’avoir intégré un pourcentage fonctionnel supérieur à 90% sans bugs bloquants de manière à garantir et maintenir les validations fonctionnelles. Les calibrations ne sont pas obligatoirement effectives (calibrations par défaut au minimum). Les 85% de fonctionnel sont négociés entre PCA et le fournisseur, avec une liste des fonctions implémentées et font l’objet d’un accord écrit. Exigences fonctionnelles implémentées : Afficher une image Traitement de la fonction tactile | G13: Le fonctionnel est opérationnel à 100 % (incluant la gestion de tous les modes dégradés). Le niveau de maturité fonctionnelle doit être établi fonction par fonction suivant le PIV et les besoins des essais sur table. | H13: 100% fonctionnel avec correction des défauts logiciels présents en B2. La précision du tactile est validé avec le cover demandé | I13: 100% fonctionnel avec correction des défauts logiciels présents en B3. | J13: Fonctionnel figé, correction des défauts présents en C4. Intégration des paramétrages SW déterminé par PCA (Table de rhéostat, table de configuration des fonctions, etc…) | K13: Fonctionnel figé
F14: Services de diagnostic : 100% implémenté et validé. | G14: Le diagnostic est implémenté et testé à 100% avec correction des défauts présents en B1 . | H14: Une validation de non régression est réalisée avec correction des défauts présents en B2. | I14: Une validation de non régression est réalisée avec correction des défauts présents en B3. | J14: Le diagnostic est figé avec correction des défauts présents en C4. Une validation complète est réalisée.
C15: Etat des livrables attendus | F15: Essais réalisés suivant plan de tests fonctionnel. | G15: Essais réalisés suivant plan de tests fonctionnel Pas de défaut de gravité A. | H15: Pas de défaut A pour la partie fonctionnelle. | I15: Pas de défaut A et B pour la partie fonctionnelle | J15: Pas de défaut A, B et C pour la partie fonctionnelle (sauf si C acceptés par déviation).
F16: Essais réalisés suivant plan de tests diagnostic. | G16: Essais réalisés suivant plan de tests diagnostic. | H16: La gestion du diagnostic sans défaut A et B. | I16: La gestion du diagnostic sans défaut A, B et C
C17: Etat des moyens de validation fournisseur | G17: Taux de couverture - 100% couches basses - 100% tests fonctionnels - Essais environnementaux : voir liste des essais demandés par PCA Moyens mis en œuvre : - Tests couches basses = Banc de tests disponible et qualifié - Tests fonctionnels = 100% des moyens de tests disponibles et qualifiés (automatique ou non => à justifier) - Tests environnementaux =Banc d’endurance et banc de surcharges de longues durées disponibles et qualifiés. | H17: Taux de couverture :100% (fonctionnel, environnementaux, couches basses) Moyens mis en œuvre :100% des moyens de tests disponibles et qualifiés (automatique ou non => à justifier).
B18: Hardware | C18: Etat physique de la pièce | E18: Schéma électronique: | F18: Schéma électronique : représentatif. | G18: Schéma électronique : figé. | H18: Schéma électronique : figé. | I18: Schéma électronique : figé | J18: Schéma électronique : figé
E19: Nomenclature: | F19: Nomenclature : représentative. | G19: Nomenclature : figée. | H19: Nomenclature : figée. | I19: Nomenclature : figée | J19: Nomenclature définitive
E20: Routage : | F20: Routage : première amélioration : non définitif. | G20: Routage : non définitif . | H20: Routage : figé (yc vernis). | I20: Routage : définitif | J20: Routage : définitif
C21: Niveau de Conformité / état des livrables attendus | D21: Couches basses | E21: Couches physique et protocole (1 & 2) : 100% implémenté et validé. Le FOURNISSEUR doit réaliser une validation complète. Matrice de conformité FNR + comptes-rendus d'essais + Plan de test fournis | F21: Couches physique et protocole (1 & 2) : 100 % implémenté et validé. Le FOURNISSEUR montre la correction des défauts vus en A0/Vf-2 - Proto B. Aucun défaut de gravité A. Matrice de conformité FNR + comptes-rendus d'essais + Plan de test fournis | G21: Couches physique et protocole (1 & 2) : 100 % implémenté et validé. Le FOURNISSEUR doit réaliser une validation complète et montrer la correction vus en B1/Vf-1 - Proto B. Aucun défaut de gravité A, B, C et D (sauf si C et D acceptés par déviation). Matrice de conformité FNR + comptes-rendus d'essais + Plan de test fournis | H21: Figé | I21: Figé | J21: Couches physique et protocole (1 & 2) : 100 % implémenté et validé. Le FOURNISSEUR réalisera les essais si et seulement si des modifications ont été apportées et/ou des défauts existaient depuis B2/Vf-ProtoC. Matrice de conformité FNR + comptes-rendus d'essais + Plan de test fournis si nécessaire. | K21: Figé
E22: Phases de vie réseau : 100% implémenté et validé. Le FOURNISSEUR doit réaliser une validation complète. Matrice de conformité FNR + comptes-rendus d'essais + Plan de test fournis | F22: Phases de vie réseau : 100% implémenté et validé. Le FOURNISSEUR montre la correction des défauts vus en A0/Vf-2 - Proto B Matrice de conformité FNR + comptes-rendus d'essais + Plan de test fournis | G22: Phases de vie réseau : 100% implémenté et validé. Le FOURNISSEUR doit réaliser une validation complète et montrer la correction vus en B1/Vf-1 - Proto B. Aucun défaut de gravité A, B, C et D (sauf si C et D acceptés par déviation). Matrice de conformité FNR + comptes-rendus d'essais + Plan de test fournis | H22: Figé | I22: Figé | J22: Phases de vie réseau : 100% implémenté et validé. Le FOURNISSEUR doit réaliser une validation complète. Aucun défaut de gravité A, B, C et D (sauf si C et D acceptés par déviation). Matrice de conformité FNR + comptes-rendus d'essais + Plan de test fournis | K22: Figé
E23: Règles de communication : 100% implémenté et validé (toutes les trames en émission et en réception doivent être gérées, au minimum avec des valeurs par défaut). Le FOURNISSEUR doit réaliser une validation complète. Matrice de conformité FNR + comptes-rendus d'essais + Plan de test fournis | F23: Règles de communication : 100% implémenté et validé. Le FOURNISSEUR montre la correction des défauts vus en A0/Vf-2 - Proto B. Matrice de conformité FNR + comptes-rendus d'essais + Plan de test fournis | G23: Règles de communication : 100% implémenté et validé. Le FOURNISSEUR doit réaliser une validation complète et montrer la correction vus en B1/Vf-1 - Proto B. Aucun défaut de gravité A, B, C et D (sauf si C et D acceptés par déviation). Matrice de conformité FNR + comptes-rendus d'essais + Plan de test fournis | H23: Figé | I23: Figé | J23: Règles de communication : 100% implémenté et validé. Le FOURNISSEUR doit réaliser une validation complète. Aucun défaut de gravité A, B, C et D (sauf si C et D acceptés par déviation). Matrice de conformité FNR + comptes-rendus d'essais + Plan de test fournis | K23: Figé
E24: + Couche 2 du diag (couche réseau pour le diag ): 100% implémenté et validé afin de tester les 100% des règles de com. Le FOURNISSEUR doit réaliser une validation complète. | F24: + Couche 2 du diag (couche réseau pour le diag ): 100% implémenté et validé. Le FOURNISSEUR montre la correction des défauts vus en A0/Vf-2 - Proto B Matrice de conformité FNR + comptes-rendus d'essais + Plan de test fournis | G24: + Couche 2 du diag (couche réseau pour le diag ): 100% implémenté et validé. Le FOURNISSEUR doit réaliser une validation complète et montrer la correction vus en B1/Vf-1 - Proto B. Aucun défaut de gravité A, B, C et D (sauf si C et D acceptés par déviation). Matrice de conformité FNR + comptes-rendus d'essais + Plan de test fournis | H24: Figé | I24: Figé | J24: Figé | K24: Figé
E25: + Services du diag (lecture et effacement défaut réseau , lecture de l’étiquette électronique) : permettant d’avoir des trames segmentées en émission et réception afin de vérifier les défauts du réseau (défaut absence de communication avec le calculateur supervisé en réception (ABSENT), défaut Muet lors de l'émission d'une trame (MUTE en CAN), défaut BUS OFF en CAN HS ou défaut de Ligne (NERR en CAN LS, Bus bloqué à l'état dominant en LIN). | H25: Figé | I25: Figé | J25: Figé | K25: Figé
E26: + Dossiers de Justification Conformité (DJC) : 3 DJC par réseau livrés (Emetteur récepteur de ligne, gestionnaire de protocole et Horloge). | G26: + Dossiers de Justification Conformité (DJC) : Les DJCs doivent être conformes à ce stade. | H26: Figé | I26: Figé | J26: Figé | K26: Figé
B28: Remarque : La définition des gravités applicables au produit est contenue dans le document QUALIT_08_4015

Sheet Maturity Requirements Disp (EN)
B2: Part maturity for each stage of the project
D4: Maturity Name | E4: VEHICULE: A0 ORGANE: Vf-2-ProtoB | F4: VEHICULE: B1 ORGANE: Vf-1-ProtoB | G4: VEHICULE: B2 ORGANE: Vf-ProtoB ou C | H4: B3 | I4: C4 | J4: VEHICULE: C5 ORGANE: Vc2-ProtoC | K4: D5
D5: Used for | E5: Unitary Tests | F5: Unitary Tests / organic Chain | G5: Integration Table | H5: Mule (Prototype Vehicles)
D6: Milestones | E6: Preliminary Definition Validation | F6: Definition Validation | I6: Agreement for IOD parts delivery | K6: Agreement for IPD parts delivery
B7: Mechanics | C7: Physical status of the part | E7: PROTOTYPE | F7: PROTOTYPE | G7: PROTOTYPE | H7: PROTOTYPE | I7: IOD (with a first tuning) | J7: IOD tuning (tuning loop finished )(1 loop minimum) | K7: IPD parts Compliant with Process Validation: even if the results of the previous phases are good, all the tests must be made again and in conformity for D5 (tactile, physicochemical and mechanical)
E8: Bulk: Without | F8: Bulk : first supplier mechanical concept | G8: Bulk : Come from the last PCA internal design. | H8: Bulk : Come from the last PCA internal design. For the parts intended to be fitted on the car, the fixation can withstand five assemblings and disassemblings.
E9: Header: | F9: Header: representative | G9: Header: representative | H9: Header: representative | I9: Header: geometrical conformity
F10: First version of the target TFT | G10: Tactile : Compliant with PCA technical specification. | H10: Display (Representative TFT, but not realized on the sérial line) | I10: Display (TFT coming from the masse production) (Serial line)
G11: Fixed choice of materials. Mechanical design frozen.
C12: Level of Conformity/state of deliverable awaited
B13: Software | C13: Level of implemented | D13: Functional Apply | E13: 30% function implemented and usable with at minimum : - 100% LVDS Low Layer - Display a picture | F13: For this delivery, it is requested from the SUPPLIER to have integrated a functional percentage higher than 90% without blocking bugs in order to guarantee and maintain the functional validations. The calibrations are not mandatory effective (calibrations by defect at least). 85% of functional are negociated between PCA and supplier, with a list of implemented functions and are subject to written agreement. Requirements for functional implementation : Display a picture Tactile function processing | G13: Functional modes are 100% operational (including all degraded modes) ; The level of functional maturity must be established function by function according to the PIV and the needs for the tests on table. | H13: 100% functional with correction of the software defects present in B2. The tactile accuracy is validated with the cover expected | I13: 100% functional with correction of the software defects present in B3. | J13: Functional is frozen, with software correction base on C4 Part maturity defects.Implementation of setting SW defined by (Diming table, functionnal setting table, other…) | K13: Functional frozen
F14: Diagnosis services : 100% implemented and validated. | G14: Diagnosis is implemented and 100% tested with correction of failures occured on B1. | H14: A validation of no backward with correction of failures occured on B2. | I14: A validation of no backward with correction of failures occured on B3. | J14: Diagnosis is frozen with correction of failures occured on C4. A full validation is performed.
C15: State of deliverable awaited | F15: Tests carried out according to functional test plan. | G15: Tests carried out according to functional test plan. No gravity A defect. | H15: No gravity A defect for functional. | I15: No gravity A & B defect for functional | J15: No gravity A, B and C defect for functional (except if C agreed by deviation)
F16: Tests carried out according to diagnostic test plan. | G16: Tests performed following diagnosis test plan. | H16: The management of the diagnosis without defect A, B. | I16: The management of the diagnosis without defect A, B and C
C17: Supplier testers status | G17: Coverage test : - 100% Low layers - 100% Functional tests - Environmental tests : see list of tests provided by PCA Means implemented : - Low layers tests = tests benches available and qualified - Functional tests = 100% of tests means available and qualified (automatic or not => to be justified) - Environmental tests = tests benches and long term overload benches available and qualified. | H17: Coverage test : 100% (functional, environmental, low layers) Means implemented : 100% of tests means available and qualified (automatic or not => to be justified).
B18: Hardware | C18: Physical status of the part | E18: Electronic diagram : | F18: Electronic diagram : representative. | G18: Electronic diagram : frozen. | H18: Electronic diagram : frozen. | I18: Electronic diagram : frozen | J18: Electronic diagram : frozen
E19: BOM: | F19: BOM : representative. | G19: BOM: frozen. | H19: BOM: frozen. | I19: BOM: frozen | J19: BOM : definitive
E20: Layout : | F20: Layout: first improvement: draft version. | G20: Layout : Draft. | H20: Layout: frozen ( conformal coating included). | I20: Layout: définitive | J20: Layout : definitive
C21: Level of Conformity / State of deliverable awaited | D21: Low layers | E21: Physical & protocol layers (1 & 2) : 100% implemented and validated. The SUPPLIER must perform a complete validation. Supplier conformity matrix + tests report + test plan delivered | F21: Physical & protocol layers (1 & 2) : 100% implemented and validated. The SUPPLIER shows the correction of the defects seen in A0/Vf-2 - Proto B. No gravity A defect. Supplier conformity matrix + tests report + test plan delivered | G21: Physical & protocol layers (1 & 2) : 100% implemented and validated. The SUPPLIER must perform a complete validation and shows the correction of the defects seen in B1/Vf-1 - ProtoB. No gravity A, B, C and D defect (except if C and D accepted by deviation). Supplier conformity matrix + tests report + test plan delivered | H21: Frozen. | I21: Frozen. | J21: Physical & protocol layers (1 & 2) : 100% implemented and validated. The SUPPLIER will perform a complete validation if and only if modifications have been done and/or defects existed since B2/Vf-ProtoC. Supplier conformity matrix + tests report + test plan delivered if necessary | K21: Frozen.
E22: Network life Phases : 100% implemented and validated. The SUPPLIER must perform a complete validation. Supplier conformity matrix + tests report + test plan delivered | F22: Network life Phases : 100% implemented and validated. The SUPPLIER shows the correction of the defects seen in A0/Vf-2 - Proto B Supplier conformity matrix + tests report + test plan delivered | G22: Network life Phases : 100% implemented and validated. The SUPPLIER must perform a complete validation and shows the correction of the defects seen in B1/Vf-1 - ProtoB. No gravity A, B, C and D defect (except if C and D accepted by deviation). Supplier conformity matrix + tests report + test plan delivered | H22: Frozen. | I22: Frozen. | J22: Network life Phases : 100% implemented and validated. The SUPPLIER must perform a complete validation. No gravity A, B, C and D defect (except if C and D accepted by deviation). Supplier conformity matrix + tests report + test plan delivered | K22: Frozen.
E23: Communication Rules: 100% implemented and validated (all the frames in transmission and reception must be managed, at least with default values). The SUPPLIER must perform a complete validation. Supplier conformity matrix + tests report + test plan delivered | F23: Communication Rules: 100% implemented and validated. The SUPPLIER shows the correction of the defects seen in A0/Vf-2 - Proto B. Supplier conformity matrix + tests report + test plan delivered | G23: Communication Rules: 100% implemented and validated. The SUPPLIER must perform a complete validation and shows the correction of the defects seen in B1/Vf-1 - ProtoB. No gravity A, B, C and D defect (except if C and D accepted by deviation). Supplier conformity matrix + tests report + test plan delivered | H23: Frozen. | I23: Frozen. | J23: Communication Rules: 100% implemented and validated. The SUPPLIER must perform a complete validation. No gravity A, B, C and D defect (except if C and D accepted by deviation). Supplier conformity matrix + tests report + test plan delivered | K23: Frozen.
E24: + Diag Layer 2 (network layer for the diag): 100% in order to test the 100% of the rules of COM. The SUPPLIER must perform a complete validation. | F24: + Diag Layer 2 (network layer for the diag): 100% implemented and validated. The SUPPLIER shows the correction of the defects seen in A0/Vf-2 - Proto B. Supplier conformity matrix + tests report + test plan delivered | G24: + Diag Layer 2 (network layer for the diag): 100% implemented and validated. The SUPPLIER must perform a complete validation and shows the correction of the defects seen in B1/Vf-1 - ProtoB. No gravity A, B, C and D defect (except if C and D accepted by deviation). Supplier conformity matrix + tests report + test plan delivered | H24: Frozen. | I24: Frozen. | J24: Frozen. | K24: Frozen.
E25: + Services of the diag (reading and erasing network defect, electronic label reading) : allowing to have signal frames segmented in emission and reception in order to check the defects of the network (defect absence of communication with the calculator supervised in reception (ABSENT), Dumb defect during the emission of a signal (TRANSFERS in CAN), defect BUS OFF in CAN HS or defect of Line (NERR in CAN LS, Bus blocked with the state dominating in LIN). | H25: Frozen. | I25: Frozen. | J25: Frozen. | K25: Frozen.
E26: + Component Justification File (CJF): 3 CJF per network delivered: transceiver, protocol manager & clock. | G26: + Component Justification File (CJF): The CJFs must be compliant at this milestone. | H26: Frozen. | I26: Frozen. | J26: Frozen. | K26: Frozen.
B28: Note : The gravity définition applied on product is include inside QUALIT_08_4015 document.
