Workbook
Name ________REF5: '[1]Page de Garde'!#REF!
Name ________REF6: '[1]Page de Garde'!#REF!
Name ________REF7: '[1]Page de Garde'!#REF!
Name ________REF8: '[1]Page de Garde'!#REF!
Name _______REF5: '[1]Page de Garde'!#REF!
Name _______REF6: '[1]Page de Garde'!#REF!
Name _______REF7: '[1]Page de Garde'!#REF!
Name _______REF8: '[1]Page de Garde'!#REF!
Name ______REF5: '[1]Page de Garde'!#REF!
Name ______REF6: '[1]Page de Garde'!#REF!
Name ______REF7: '[1]Page de Garde'!#REF!
Name ______REF8: '[1]Page de Garde'!#REF!
Name _____REF5: '[1]Page de Garde'!#REF!
Name _____REF6: '[1]Page de Garde'!#REF!
Name _____REF7: '[1]Page de Garde'!#REF!
Name _____REF8: '[1]Page de Garde'!#REF!
Name ____REF5: '[1]Page de Garde'!#REF!
Name ____REF6: '[1]Page de Garde'!#REF!
Name ____REF7: '[1]Page de Garde'!#REF!
Name ____REF8: '[1]Page de Garde'!#REF!
Name ___REF5: '[1]Page de Garde'!#REF!
Name ___REF6: '[1]Page de Garde'!#REF!
Name ___REF7: '[1]Page de Garde'!#REF!
Name ___REF8: '[1]Page de Garde'!#REF!
Name __REF5: '[1]Page de Garde'!#REF!
Name __REF6: '[1]Page de Garde'!#REF!
Name __REF7: '[1]Page de Garde'!#REF!
Name __REF8: '[1]Page de Garde'!#REF!
Name _53751_560T0: #REF!
Name _REF5: '[1]Page de Garde'!#REF!
Name _REF6: '[1]Page de Garde'!#REF!
Name _REF7: '[1]Page de Garde'!#REF!
Name _REF8: '[1]Page de Garde'!#REF!
Name aa: #REF!
Name Act_C: #REF!
Name Act_EC: #REF!
Name Act_R: #REF!
Name Async_Hp_Task_Load: #REF!
Name Async_Hp_Task_Load_0rpm: #REF!
Name Async_Hp_Task_Load_2000rpm: #REF!
Name Async_Lp_Task_Load_0rpm: #REF!
Name Async_Lp_Task_Load_2000rpm: #REF!
Name Base: [3]RVCV!$CV:$ER
Name champs_synchronisés: #REF!
Name CSEO_CSIV07_1580__2: [4]!_xlbgnm.A1
Name CSEO_CSIV07_1580__2: [4]!_xlbgnm.A1
Name Declinaison: [5]bdmux!$U$4:$AH$5,[5]bdmux!$AJ$4:$DK$5
Name Données: #REF!
Name Données_207_Madrid: OFFSET(#REF!,0,0,1,MATCH(MAX(#REF!),#REF!,0))
Name Données_207_Madrid_4SG: OFFSET(INDIRECT("Graphiques!L"&MATCH("Résultats IQF+IQA 207 82",#REF!,0)&"C"&#REF!,0),0,0,1,MATCH(MAX(#REF!),#REF!,0)-#REF!+1)
Name Données_207_Madrid_IQA_4SG: OFFSET(INDIRECT("Graphiques!L"&MATCH("Résultats IQA 207 82",#REF!,0)&"C"&#REF!,0),0,0,1,MATCH(MAX(#REF!),#REF!,0)-#REF!+1)
Name Données_207_Madrid_IQF_4SG: OFFSET(INDIRECT("Graphiques!L"&MATCH("Résultats IQF 207 82",#REF!,0)&"C"&#REF!,0),0,0,1,MATCH(MAX(#REF!),#REF!,0)-#REF!+1)
Name Données_207_Poissy: OFFSET(#REF!,0,0,1,MATCH(MAX(#REF!),#REF!,0))
Name Données_207_Poissy_4SG: OFFSET(INDIRECT("Graphiques!L"&MATCH("Résultats IQF+IQA 207 81",#REF!,0)&"C"&#REF!,0),0,0,1,MATCH(MAX(#REF!),#REF!,0)-#REF!+1)
Name Données_207_Poissy_IQA_4SG: OFFSET(INDIRECT("Graphiques!L"&MATCH("Résultats IQA 207 81",#REF!,0)&"C"&#REF!,0),0,0,1,MATCH(MAX(#REF!),#REF!,0)-#REF!+1)
Name Données_207_Poissy_IQF_4SG: OFFSET(INDIRECT("Graphiques!L"&MATCH("Résultats IQF 207 81",#REF!,0)&"C"&#REF!,0),0,0,1,MATCH(MAX(#REF!),#REF!,0)-#REF!+1)
Name Données_207_Tranava_4SG: OFFSET(INDIRECT("Graphiques!L"&MATCH("Résultats IQF+IQA 207 76",#REF!,0)&"C"&#REF!,0),0,0,1,MATCH(MAX(#REF!),#REF!,0)-#REF!+1)
Name Données_207_Tranava_IQA_4SG: OFFSET(INDIRECT("Graphiques!L"&MATCH("Résultats IQA 207 76",#REF!,0)&"C"&#REF!,0),0,0,1,MATCH(MAX(#REF!),#REF!,0)-#REF!+1)
Name Données_207_Tranava_IQF_4SG: OFFSET(INDIRECT("Graphiques!L"&MATCH("Résultats IQF 207 76",#REF!,0)&"C"&#REF!,0),0,0,1,MATCH(MAX(#REF!),#REF!,0)-#REF!+1)
Name DWG_DATE: #REF!

Sheet Cover - History - Status
A1: DMOV
C2: Docinfo Ref : | D2: Version : | E2: Review Status : | F2: Current Evaluation :
B3: Project Document | C3: <fill doc ref here> | D3: =LOOKUP("zz",B50:B68) -> 1.0 | E3: =C73 -> Not Started | F3: =B77 -> 0
B4: Template Document | C4: DMOV_ELE06_0050 | D4: =LOOKUP("zz",B10:B45) -> Details of the modifications in document: 21067_23_00063
D6: Project : Supplier: | E6: <Fill project name here>
D7: Supplier : | E7: <Fill Supplier name here>
C10: SW Development Methods Overview and Verification (DMOV) Evaluation Grids for SW Development Rules, SW Safety and Cybersecurity
B12: Template History
B13: Version (DocInfo) | C13: Date | D13: Author | E13: Modifications
B14: V8 | C14: 12 December 2013 | D14: Fabrice BEDOUCHA | E14: Merge between software development rules V7 and software safety management checklist.
B15: V8.1 | C15: 21th August 2014 | D15: Fabrice BEDOUCHA | E15: Adding requirement REGLESSW-ST-11-007 Modifying of REGLESSW-ST-63-002 and REGLESSW-ST-63-003.
B16: V9 | C16: 13 October 2014 | D16: Yann-Mikaël FOLL | E16: Status of coding rules / ISO 26262 questions has been refined; distinction between conformity status, implementation satus, validation status. Deadlines has been refined as well; distinction between implementation delivery and validation delivery.
B17: V9.1 | C17: 11 December 2014 | D17: Fabrice BEDOUCHA | E17: Adding requirements REGLESSW-ST-63-005(0) and REGLESSW-ST-8-006(0)
B18: V9.2 | C18: 12 January 2015 | D18: Fabrice BEDOUCHA | E18: Adding requirement REGLESSW-ST-8-007(0)
B19: V9.3 | C19: 28 January 2015 | D19: Fabrice BEDOUCHA | E19: Replace µP by microcontroller Change of ISO 2626 Checklist numbers
B20: V9.4 | C20: 15 December 2015 | D20: S. BROUSTE | E20: - Worksheets "WP Mapping", "Graph Avancement", "Planning Info" created - Worksheet "Evaluation Status", separated from "Metrics" - "Are there sw components or functions safety related left without any technical safety measures? Added to ISO question ISO26262-6.7_140 - "Bug" in the graph because of the 2 temporal axes (not fixed) - Proposal to add a QIA worksheet and centralized all Q/A on these topics and show at the end that everything is closed; - actually, only the 4 first worksheets should be sent to the supplier : create an export / import macro?
B21: V15.1 | C21: 26/09/2017 | D21: S. BROUSTE | E21: in this worksheet, modification of cells that shall contain : - the reference of this document for the project - the reference of the DIA (if applicable) once it has been defined (which template? STLA? Supplier's one?) ; it shall be defined by the Functional Safety Managers (FSM) - this history shall be erased and replaced by the project document History
B22: V16 | C22: 12/01/2018 | D22: Fabrice BEDOUCHA | E22: Adding cybersecurity requirements
B23: V18 | C23: 27/02/2019 | D23: Farid MALLOULI | E23: Added global metrics for tracking review progress and conformity level with simpler metrics
B24: V19 | C24: 03/06/2019 | D24: Fabrice BEDOUCHA | E24: Update after internal reviews Software Development rules: REGLESSW-ST-5-004(0): new REGLESSW-ST-63-006(0): new REGLESSW-ST-63-007(0): new REGLESSW-ST-7-003(4): modified REGLESSW-ST-9-002(2): modified REGLESSW-ST-12-003(2): modified REGLESSW-ST-14-001(2): modified REGLESSW-ST-14-002(2): modified ISO 26262 checklist: ISO26262-6.7_30: modified ISO26262-8.11_10: new ISO26262-8.11_20: new ISO26262-8.12_10: new ISO26262-8.12_20: new
... B42: V37 | C42: 31 July 2025 | D42: Fabrice Bedoucha | E42: Answer to STLA SW Dev. Rules: REGLESSW-ST-62-004: New REGLESSW-ST-62-005: New REGLESSW-ST-63-001: New REGLESSW-ST-11-024: New REGLESSW-ST-11-025: New REGLESSW-ST-11-026: New REGLESSW-ST-8-007: Modified REGLESSW-ST-8-009: New REGLESSW-ST-8-010: New
B44: Details of the modifications in document: 21067_23_00063
B46: Do not erase this line, insert new lines above to keep formula for template version used in the head of document
B48: Document History
B49: Version (DocInfo) | C49: Date | D49: Author | E49: Modifications
B50: 1.0
B70: Evaluation Status
B71: To be filled by Stellantis (STLA)
B73: Review status | C73: Not Started
B75: Conclusion
B76: Level | C76: Current global Evaluation
C77: To be filled by STLA (mandatory)
B80: =CONCATENATE("Number of open action plans = ",SUM(COUNTIF(#REF!,"ongoing"),COUNTIF('ISO 26262-2018 Checklist'!P4:P59,"ongoing"),COUNTIF('Answer to security rules'!P4:P12,"ongoing"))," ( ",COUNTIF(#REF!,"ongoing")," in SW Dev Rules, ",COUNTIF('ISO 26262-2018 Checklist'!P4:P59,"ongoing")," in ISO26262 and ",COUNTIF('Answer to security rules'!P4:P12,"ongoing")," in Security Rules)") -> #REF!
B82: Project Planning Information
B83: Please always keep this planning information up to date (used for KPI calculation)
B85: Main SW Deliveries and milestones | E85: To be filled and maintained up to date (see help to fill project milestone on the right)
B87: RFQ Start | C87: RFQ End | D87: V1 | E87: V2 | F87: V3 | G87: V4 | H87: V5 | L87: DMOV Milestones | M87: Description | N87: Former project milestone
L88: RFQ Start | M88: Start of consultation phase | N88: RFQ Start
B89: Vx can be changed according to software version or milestones used in the project | L89: RFQ End | M89: End of consultation phase | N89: RFQ End
L90: V1 | M90: First full spec SW version | N90: ~Vf SW
...

Sheet ReadMe
A1: DMOV
A2: This document is applied to all embedded software developed for Stellantis. The supplier shall apply each requirement. However the supplier can propose an alternative solution or explain the reason why it cannot fulfill the requirement. The aim is not to get all requirements applied but to get a consistent set of applied requirements, especially in term of software safety. These requirements are not exhaustive and it is up to the supplier to apply other requirements, for example based on its lessons learned, which can ensure the robustness of its product. These requirements are constantly evolving according to lessons learned from projects. So please note, that in case of lesson learned with high impact, new applicable requirements could be added to this document. STLA answer is facultative in colums "STLA review status", however, even if STLA answer is "OK", the supplier stays responsible for its technical choices, implementation and tests.
A3: How to fill the document : - In column C, the supplier indicates the expected level of conformity. if it is "FC : Fully Compliant" - "LC : Largely Compliant" - "PC : Partially Compliant" - "NC: No Compliant" or if the requirement is "NA: Not Applicable". Note that column C does not reflect the current conformity level but the expected one at the end of the project. - In column D, the supplier indicates the current implementation status. - In column E, the supplier indicates the software version for which the implementation of the requirement is planned. - In column F, the supplier indicates in which software version the requirement is really implemented. - In column G, the supplier indicates the current validation status. - In column H, the supplier indicates the software version for which the validation of the requirement is planned. - In column I, the supplier indicates in which software version the requirement is really validated. - In column J, the supplier adds a comment to explain its choices, and all necessary informations on implementation and validation progression. In particular, if column C is different from FC (Fully Compliant), the supplier shall add an explanation here. For Request For Quotation, only columns C, E, H and J shall be filled in sheets: - Answer to STLA SW Dev. Rules - ISO 26262-2018 Checklist - Answer to security rules - These requirements are applicable to ECUs without cybersecurity. In the following cases, for a single ECU, several DMOVs have to be filled: - In case of several microcontrollers: one DMOV per microcontroller (otherwise it shall be justified) - In case of several Tier N suppliers: one DMOV between STLA and Tier 1 + additional DMOV between each Tier 1 and Sub Suppliers
A4: To ease the review, SW Dev Rules and ISO26262 contains a classification of questions, to focus on specific topics (definition in hidden sheet).
A5: The Key points, identified by a 'X' in each checklist, have to be reviewed in priority.
A6: In case of action plan defined on any question, please fill the action plan status in the corresponding column at the end of the checklists.
A8: Note: Do not change the format of the document (new column, new line, content of the columns…) in order to keep formulas working properly (keep excel sheet protection activated)
B9: Frontsheet - Metrics explanation
A11: The frontsheet of this document contains several information explained here (some values are filled just for the example)
A13: The first part contains global project information, the user has to fill document reference, Supplier and Project name.
A14: Only editable cells can be modified, the sheet is protected (no password). Some lines are grouped to hide detailed level of information.
A22: After document history, the Evaluation Status section contains information to be filled by STLA along the review.
A23: During the review, some action plans could be defined in the checklists (see last column of each checklist), they are reported here.
A24: All actions plan have to be closed before the defined milestone.
A37: An important section is the project planning , it must be always kept up to date in order for the review progress calculation formulas to work.
A45: The Key Progress Indicators contains useful metrics to track review progress and conformity level againt project planning.
A46: The metrics are colored in orange (up to 20% late) and red (more than 20% late) if review is not on track compared to expected targets.
A47: For each metrics a table gives this expected target for the related milestone.
A51: Example below for RFQ phase, the line 'expected' is the calculation of expected target (at least) for current date considering planning information.
A52: Some questions, identified as 'Key Points' have a specific metrics because they have too be all reviewed and agreed before RFQ End.
... A89: Finally, a graphical view of the review progress is provided at the end of the frontsheet. The dots should be all above the corresponding curve.

Sheet Answer to STLA SW Dev. Rules
A1: DMOV
A2: Requirement | B2: Description | C2: Supplier answer | K2: STLA review status
C3: Conformity Status | D3: Implementation Status | E3: Implementation delivery (planned) | F3: Implementation delivery (real) | G3: Verification & Validation Status | H3: Verification & Validation delivery (planned) | I3: Verification & Validation delivery (real) | J3: Justification/Answer | K3: Conformity Status | L3: Implementation Status | M3: Verification & Validation Status | N3: Remark | O3: Documents or Meeting Minutes References | P3: Action Plan | Q3: Topic classification | R3: Key Pt
A4: GENERIC RULES | V4: NA | W4: Not Applicable | X4: =COUNTIF(C$5:C$151,"NA") -> 23 | AA4: OK | AB4: =COUNTIF(K$5:K$151,"OK") -> 0 | AD4: OK | AE4: OK | AF4: =COUNTIF(K$5:K$256,"OK") -> 0 | AH4: Action Plan
A5: REGLESSW-ST-5-003(2) | B5: The reason for the last reset shall be memorized and accessible | C5: FC | J5: TIANMA: MCU has Reg/EEPROM to store last reset reason for HW reset reason. EEPROM has store reset reason for SW reset reason before reset handle | P5: - | Q5: SW Design Rules and technical REX | R5: X | V5: NC | W5: No compliant | X5: =COUNTIF(C$5:C$151,"NC") -> 0 | AA5: NOK | AB5: =COUNTIF(K$5:K$151,"NOK") -> 0 | AD5: NOK | AE5: NOK | AF5: =COUNTIF(K$5:K$256,"NOK") -> 0 | AH5: -
A6: REGLESSW-ST-5-002(4) | B6: A mechanism shall be developed to detect micro continuously resetting (excluding the case of Power on Reset). Once detected, the associated behavior should: • First, assure security, • Then, protect the rest of the car against battery failure, • Last, avoid system failure The mechanism of detection of continuous resets and the behavior in case of detection shall be described and approved by STLA. | C6: FC | J6: If the watchdog reset is detected for 10 consecutive times, the MCU will stop the watchdog reset and also cease operation. | P6: - | Q6: SW Design Rules and technical REX | V6: PC | W6: Partly compliant | X6: =COUNTIF(C$5:C$151,"PC") -> 0 | AA6: NA | AB6: =COUNTIF(K$5:K$151,"NA") -> 0 | AD6: TBA | AE6: To Be Assessed | AF6: =COUNTIF(K$5:K$256,"TBA") -> 0 | AH6: ongoing
A7: REGLESSW-ST-5-001(1) | B7: For any usage of CRC mechanism, the choice of the polynomial (size and degree) shall be justified. | C7: FC | J7: TIANMA: CRC32 will be done in NVM module. | P7: - | Q7: SW Design Rules and technical REX | V7: LC | W7: Largely compliant | X7: =COUNTIF(C$5:C$151,"LC") -> 6 | AD7: NA | AE7: Not Applicable | AF7: =COUNTIF(K$5:K$256,"NA") -> 0 | AH7: closed
A8: REGLESSW-ST-5-004(0) | B8: If the software update includes the update of the firmware of a sub-chip (GPS, Bluetooth, HSM, Ethernet switch etc …) this update shall be done during installation of the new software and not during nominal new software execution. | C8: FC | P8: - | Q8: SW Design Rules and technical REX | R8: X | V8: FC | W8: Fully compliant | X8: =COUNTIF(C$5:C$151,"FC") -> 74
A9: MEMORY MANAGEMENT
A10: REGLESSW-ST-61-001(2) | B10: After wake up, RAM shall be tested. This test could consist in writing then reading a pattern (0x55AA classically), in every RAM address. In case of error, a reset shall be forced. If the complete test is not compatible with the init timing required for the component, test can be reduced to critical variables. | C10: LC | J10: TIANMA: SRAM include Stack. Init RAM,No-Init RAM and heap area. Due to some key data should store in RAM, only Init RAM area can be tested. Will be implemented. | P10: - | Q10: SW Design Rules and technical REX
A11: REGLESSW-ST-62-001(2) | B11: RAM shall be initialized at each wake up with a justified value. If this is not possible (RAM_NO_INIT mechanism for example), final choice done should be justified. Supplier shall provide to STLA the list of data stored in the non initialized memory. | C11: FC | J11: SRAM include Stack. Init RAM,No-Init RAM and heap area. | P11: - | Q11: SW Design Rules and technical REX | R11: X
A12: REGLESSW-ST-62-004(0) | B12: If supplier uses RAM NO INIT instead of Non Volatile Memory, it shall be justified. In particular in case of reset, there shall not be any malfunction when using RAM NO INIT. | C12: FC | J12: Due to some key data should store in RAM, only Init RAM area can be tested. Will be implemented
A13: REGLESSW-ST-62-005(0) | B13: Data saved in Non Volatile Memory and not erased in case of software update shall be listed and justified. | C13: FC
A14: REGLESSW-ST-63-005(0) | B14: If microcontroller allows ECC (Error Correction Code) management in flash and/or RAM it shall be activated. | C14: FC | J14: TIANMA: Microcontroller(CYT2B75) support ECC ,and it will be activated. | P14: - | Q14: SW Design Rules and technical REX | R14: X
A15: REGLESSW-ST-63-006(0) | B15: The supplier shall prove that during all the use of its product, the maximal number of writing in the EEPROM or Flash is never reached. A study shall be done and shared with STLA for validation. | C15: FC | J15: TIANMA: For this project, Tianma will purchase fee fls from Infineon , this third party mechanisms will average number of brush per area | P15: - | Q15: SW Design Rules and technical REX | R15: X
A16: REGLESSW-ST-63-007(1) | B16: The supplier shall guaranty data retention in non-volatile memory during the complete period of use of its product. A study shall be done and shared with STLA for validation. | C16: FC | J16: TIANMA: The data has store in NVM map excel | P16: - | Q16: SW Design Rules and technical REX | R16: X
A17: REGLESSW-ST-63-008(0) | B17: The use of common data sections, where the same address in memory is shared between two or more different symbols shall be avoided, e.g. common data buffer for different CAN messages. If used, it shall be justified. The reason of that choice is to avoid production of not portable software. Moreover, it could potentially introduce side effects, difficult to estimate. | C17: FC | J17: TIANMA: There is no situation where different data uses a common data address
A18: REGLESSW-ST-63-009(0) | B18: In case of different memory partitions (Flash and/or RAM) with different performances (e.g. ram partitions dedicated to one core vs global shared RAM partition, ...). The allocation strategy shall be defined and justified | C18: NA | J18: TIANMA: No Share memory will be used in this project
A19: Specific to "Autosar Classic - Operating System like OSEK - Scheduler and below"
A20: REGLESSW-ST-61-002(2) | B20: After wake up, flash shall be tested. This test could consist in reading flash and calculate a CRC, which CRC shall be equal to a CRC already written in flash. If the complete test is not compatible with the init timing required for the component, test can be reduced to critical code areas. | C20: LC | J20: TIANMA: Flash code area is too big size, if check all data need spend more than 100ms, it will effect start-up time.So only check NVM area in flash . After system wakeup, will check NVM data CRC value whethter equal to CRC byte. | P20: - | Q20: SW Design Rules and technical REX
A21: REGLESSW-ST-62-003(2) | B21: If microcontroller contains some non used FLASH or ROM, this one shall be initialized with the code of an instruction forcing a reset. | C21: FC | J21: TIANMA: useless ROM address will fullfill with 0xFF via IDE setting | P21: - | Q21: SW Design Rules and technical REX | R21: X
A22: REGLESSW-ST-63-001(1) | B22: Executable code loading from FLASH, EEPROM or ROM to RAM shall be justified and protected (specific CRC for example). | C22: LC | J22: After system wakeup, will check NVM data CRC value whethter equal to CRC byte.
A23: REGLESSW-ST-63-002(4) | B23: EEPROM data blocks shall be protected with a CRC. This CRC shall be calculated at each writing and checked at each reading. Every non protected area shall be justified. The aim is to manage two constraints : - Ageing EEPROM memory cells after many writings. - Power off during writing in EEPROM A similar mechanism shall be put in place in case of EEPROM emulation in flash. | C23: FC | J23: TIANMA: EEPROM divide by 4 blocks, every blocks has dependence CRC. If data is changed, will write whole block. Not effect age of other data. If power of during writing EEPROM, after reset will check EEPROM CRC. If one block CRC is incorrectly, will use default data which store in ROM for this block. | P23: - | Q23: SW Design Rules and technical REX | R23: X
A24: REGLESSW-ST-63-015(0) | B24: EEPROM emulation in Data Flash (E.g. Autosar NVM classical design solution) introduces flash page switching and flash page erase operations (long process) during ECU activity. This design solution opens the door to two use cases: - Timing impact when the page swap becomes necessary (nominal case or error recovery) - Power off during page writing or page erase Design solution shall be associated with efficient management of those two use cases and supplier shall document how the management of them is compatible with all the requirements of the ECU related to: - Error recovery, - timing requirements at startup and during shutdown when startup demand happens during shutdown, in nominal mode and also during error recovery. The validation plan shall address and test all the corresponding use cases and demonstrate the robustness of the software. | C24: FC | J24: Display will check Wake up pin status before pull down MCU pin to low and complete power off sequence,if Wake up pin status is high,then will not pull down MCU pin to low and execute power on sequence. The validation plan will provide and review with STLA
A25: REGLESSW-ST-63-003(3) | B25: Copying an EEPROM block into RAM memory, in order to increase response time at runtime or to reduce EEPROM access is possible. Supplier shall provide to STLA mechanism used to guarantee a safe behavior at the init time after the reset. A similar mechanism shall be put in place in case of EEPROM emulation in flash. | C25: FC | J25: TIANMA: FEE will mirror the NVM data in RAM and to make sure the access NVM are under control | P25: - | Q25: SW Design Rules and technical REX | R25: X
A26: REGLESSW-ST-63-004(0) | B26: Dynamic memory allocation is forbidden. | C26: FC | J26: TIANMA: Dynamic memory allocation is not used.Code review will check dynamic memory allocation. | P26: - | Q26: SW Design Rules and technical REX | R26: X
A27: Specific to "Multiple OS/Virtualization"
A28: REGLESSW-ST-63-010(0) | B28: The Flash and RAM allocation to the different virtualized contexts (VMs, …) shall be justified. This strategy and justification shall include also the eventual RAM/Flash dedicated to some HW accelerators (GPU, …) | C28: NA | J28: TIANMA: Display is used MCU, no virtualization
A29: REGLESSW-ST-63-011(0) | B29: The strategy to manage shared memory between the different virtualized contexts shall be explained and justified. In particular, it will be explained how to avoid race condition issues. | C29: NA | J29: TIANMA: Display is used MCU, no virtualization
A30: REGLESSW-ST-63-013(0) | B30: In case of shared GPU and/or shared Display between several virtualized contexts, the strategy shall be explained and justified. In particular, the way eventual different HMI/Graphical frameworks are at the end shared in a single GPU shall be detailed and justified. | C30: NA | J30: TIANMA: Display is used MCU, no virtualization
A31: REGLESSW-ST-63-014(0) | B31: The peripherals sharing strategy shall be explained and justified (E.g. Ethernet connection). | C31: NA | J31: TIANMA: Display is not sharing peripherals.
A32: Specific to "Extra cores (HSM, Low consumption, …)"
A33: REGLESSW-ST-63-012(0) | B33: In case of shared memory between the main cores and those extra cores, the strategy of management of this shared memory shall be detailed and justified. In particular, it will be explained how to avoid race condition accessing shared areas. | C33: NA | J33: TIANMA: Display is not sharing memory.
A34: INTERRUPTS MANAGEMENT
A35: REGLESSW-ST-7-001(3) | B35: A handler function shall be associated with every interrupt and exception vectors. If an interrupt is not used, it is associated with a function forcing a reset and keeping a trace of the reset. Unexpected exceptions shall be handled by an appropriate reaction (most often a reset). | C35: FC | J35: TIANMA: If an useless interrupt be abnormal triger, SW should store reset reason in EEPROM and execute system reset. | P35: - | Q35: SW Design Rules and technical REX | R35: X
A36: REGLESSW-ST-7-002(0) | B36: A non used interrupt shall be masked | C36: FC | J36: TIANMA: NVIC init will disable all interrupt. If one interrupt will be used, will be enable | P36: - | Q36: SW Design Rules and technical REX | R36: X
A37: REGLESSW-ST-7-003(4) | B37: A protection mechanism shall be developed against inopportune interrupts (more than x executions of the interrupt in less than y ms) to protect the execution of the rest of the program. | C37: FC | J37: TIANMA: WDGM will detect the interrupt excute count. | P37: - | Q37: SW Design Rules and technical REX
A38: REGLESSW-ST-7-004(0) | B38: Non maskable interrupt usage (except for the watchdog) shall be justified. Especially, every parts of code developed to normally run with masked interrupts shall be designed to be interruptible by these non maskable interrupts. | C38: FC | P38: - | Q38: SW Design Rules and technical REX | R38: X
A39: REGLESSW-ST-7-005(1) | B39: Changing interrupt priority at runtime is forbidden. | C39: FC | J39: TIANMA: The priority of interrupt has set at module init for once. It can not be changed at runtime | P39: - | Q39: SW Design Rules and technical REX | R39: X
A40: REGLESSW-ST-7-006(1) | B40: Executing parts of code with interrupts masked or partially masked shall be justified and be as short as possible (typically 50µs). Supplier shall calculate all critical sections in its code and shall guarantee that every real time requirements are fulfilled. | C40: FC | J40: TIANMA: Code view will check the Enter/Exit critical section handle | P40: - | Q40: SW Design Rules and technical REX | R40: X
...

Sheet ISO 26262-2018 Checklist
A1: DMOV
A2: Number | B2: Question | C2: Supplier Answer (please explain in column "Answer") | K2: STLA review status
C3: Conformity Level | D3: Implementation / application status | E3: Implementation delivery (planned) | F3: Implementation delivery (real) | G3: Verification & Validation status | H3: Verification & Validation delivery (planned) | I3: Verification & Validation delivery (real) | J3: Justification/Answer | K3: Conformity Level | L3: Implementation Level | M3: Verification & Validation Level | N3: Comments | O3: Documents or Meeting Minutes References | P3: Action Plan | Q3: Topic Classification | R3: Key Pt
A4: General topics for the product development at the software level | AA4: Action Plan :
A5: ISO26262-6.5_00(0) | B5: What is the highest ASIL for the ECU and what is the highest ASIL for the software? | C5: FC | E5: B3 | H5: B3 | J5: the highest ASIL for ECU and software is ASIL B | L5: NA | M5: NA | P5: - | Q5: General Topics | V5: NA | W5: Not Applicable | X5: =COUNTIF(C$6:C$177,"NA") -> 5 | AA5: -
A6: ISO26262-6.5_10(0) | B6: Are software safety activities described? Especially, are all chapters of the Part 6 concerned by this description and are supplier deliverables mentioned? ISO 26262-6:2018 - 5.2 | C6: FC | E6: B3 | H6: B3 | J6: the safety activities described in safety plan | P6: - | Q6: Planification of SW Safety activities | V6: NC | W6: Non Compliant | X6: =COUNTIF(C$6:C$177,"NC") -> 0 | AA6: ongoing
A7: ISO26262-6.5_20(0) | B7: Are software safety activities scheduled? ISO 26262-6:2018 - 5.4.1 | C7: FC | E7: B3 | H7: B3 | J7: the safety activities cheduled in timeline | P7: - | Q7: Planification of SW Safety activities | V7: PC | W7: Partly compliant | X7: =COUNTIF(C$6:C$177,"PC") -> 0 | AA7: closed
A8: ISO26262-6.5_30(0) | B8: What is the modelling language if any and what is the coding language? ISO 26262-6:2018 - 5.4.2 | C8: NA | J8: Coding language: C, modelling language is UML in software architecture design and detail design. | L8: NA | M8: NA | P8: - | Q8: General Topics | V8: LC | W8: Largely compliant | X8: =COUNTIF(C$6:C$177,"LC") -> 0
A9: ISO26262-6.5_40(0) | B9: What are the topics that are fulfilled in Table 1 and how are they fulfilled? ISO 26262-6:2018 - 5.4.3 | C9: FC | E9: B3 | H9: B3 | J9: The software meets the rules required by ASIL B 1a Enforcement of low complexity 1b Use of language subsets 1c Enforcement of strong typing+ 1f Use of unambiguous graphical representation 1g Use of style guides 1h Use of naming conventions | P9: - | Q9: SW Unit Design and Verification (incl. static analyses) | R9: X | V9: FC | W9: Fully compliant | X9: =COUNTIF(C$6:C$177,"OK") -> 0
A10: ISO26262-6.5_60(0) | B10: Are coding guidelines described and applied? ISO 26262-6:2018 - 5.4.3 | C10: FC | E10: B3 | H10: B3 | J10: yes, TIANMA has code guidelines document. | N10: Note: it should be aligned with answer to REGLESSW-ST-14-001(2) and REGLESSW-ST-14-002(2) in sheet "Answer to STLA SW Dev. Rules" | P10: - | Q10: SW Unit Design and Verification (incl. static analyses)
A11: ISO26262-6.5_70(0) | B11: Are tooling guidelines described and applied? ISO 26262-6:2018 - 5.4.3 | C11: FC | E11: B3 | H11: B3 | J11: Yes, tool guideline is avalible in system | P11: - | Q11: Confidence in tools
A12: Specification of software safety requirements | V12: OK | W12: OK | X12: =COUNTIF(L$2:L$177,"OK") -> 0
A13: ISO26262-6.6_10(0) | B13: Are safety related functions identified? ISO 26262-6:2018 - 6.4.1 | C13: FC | E13: B3 | H13: B3 | J13: Safety related function will be presented in TSR/SSR allocated to Software. | P13: - | Q13: Software Safety requirements and traceability | V13: NA | W13: Not Applicable | X13: =COUNTIF(L$2:L$177,"NA") -> 7
A14: ISO26262-6.6_20(0) | B14: Are software safety requirements clear and complete? ISO 26262-6:2018 - 6.4.2 | C14: FC | E14: B3 | H14: B3 | J14: Safety related function will be presented in TSR/SSR allocated to Software. | P14: - | Q14: Software Safety requirements and traceability | V14: TBA | W14: To Be Assessed | X14: =COUNTIF(L$2:L$177,"TBA") -> 0
A15: ISO26262-6.6_30(0) | B15: Is ASIL for software justified? Are different ASILs managed? ISO 26262-6:2018 - 6.4.3 | C15: FC | E15: B3 | H15: B3 | J15: ASILB requirments will be defined in TSR, QM requirements will be defined in system requirements | P15: - | Q15: Software Safety requirements and traceability | V15: NOK | W15: NOK | X15: =COUNTIF(L$2:L$177,"NOK") -> 0
A16: ISO26262-6.6_40(0) | B16: Does Hardware Software Interface document exist and is complete? ISO 26262-6:2018 - 6.4.4 | C16: FC | E16: B3 | H16: B3 | J16: Hardware Software Interface will be presented in HSIS allocated to Software. | P16: - | Q16: Software Safety requirements and traceability
A17: ISO26262-6.6_50(0) | B17: Are software safety requirement reviewed? ISO 26262-6:2018 - 6.4.7 | C17: FC | E17: B3 | H17: B3 | J17: Review activities will be planned in software timeline. | P17: - | Q17: Software Safety requirements and traceability | R17: X
A18: SW architectural design
A19: ISO26262-6.7_10(0) | B19: What is the notation to describe software architecture? ISO 26262-6:2018 - 7.4.1 | C19: FC | E19: B2 | H19: B2 | J19: TianMa product will follow: 1a Natural language 1b Informal natations | L19: NA | M19: NA | P19: - | Q19: SW Architecture and SW Safety Analysis
A20: ISO26262-6.7_20(0) | B20: Is software architecture justified to guarantee verifiability, suitability, feasibility, testability and maintainability? ISO 26262-6:2018 - 7.4.2 | C20: FC | E20: B3 | H20: B3 | J20: Architecture will be done Justification table is existing. | P20: - | Q20: SW Architecture and SW Safety Analysis
A21: ISO26262-6.7_30(0) | B21: What are the principles for software architectural design that are fulfilled in Table 3 and how are they fulfilled? ISO 26262-6:2018 - 7.4.3 | C21: FC | E21: B3 | H21: B3 | J21: TianMa product will follow: 1a Appropriate hierarchical structure of the software components 1b Restricted size and complexity of software components 1d Strong cohesion within each software component 1e Loose coupling between software components 1f Appropriate scheduling properties 1i Appropriate management of shared resources | P21: - | Q21: SW Architecture and SW Safety Analysis | V21: OK | W21: OK | X21: =COUNTIF(L$2:L$177,"OK") -> 0
A22: ISO26262-6.7_50(0) | B22: Is architecture described (static design aspect of the software architectural elements and dynamic design aspect of the software architectural elements)? ISO 26262-6:2018 - 7.4.5 | C22: FC | E22: B3 | H22: B3 | J22: both of them will be presented in software architecture design. | P22: - | Q22: SW Architecture and SW Safety Analysis | V22: NOK | W22: NOK | X22: =COUNTIF(L$2:L$177,"NOK") -> 0
A23: ISO26262-6.7_60(1) | B23: Is software partitioning used? If yes, does a SW partition contain only components with the same ASIL? Otherwise, how do you guarantee the Freedom From Interference of the lower ASILs components to the highest one? - For example if you have a partition with ASIL QM and ASIL B components or ASIL A and ASIL B components - Please share a table with the exhaustive list of components with their ASIL and partition allocation. ISO 26262-6:2018 - 7.4.9 | C23: FC | E23: B3 | H23: B3 | J23: SW ASIL B partition contain touch and telltale, the other areas are QM. | P23: - | Q23: SW Architecture and SW Safety Analysis | V23: NA | W23: Not Applicable | X23: =COUNTIF(L$2:L$177,"NA") -> 7
A24: ISO26262-6.7_70(0) | B24: What are the safety analyses applied at the architectural level? Describe the methodologies and the link with the architecture justification and safety mechanisms. ISO 26262-6:2018 - 7.4.10 | C24: FC | E24: B3 | H24: B3 | J24: SW FMEA and DFA will be done. Even, according to the preferable ASIL B, some key elementary and interface will be analyzed via SW FMEA to see if any risk can be identified and migrated. | P24: - | Q24: SW Architecture and SW Safety Analysis | R24: X
A25: ISO26262-6.7_80(0) | B25: How freedom from interference or sufficient independence between software components is managed? Which failures do you consider and what are the related safety mechanisms? ISO 26262-6:2018 - 7.4.11 | C25: FC | E25: B3 | H25: B3 | J25: software components are managed with clear interface defition, and strategy to exchange data, the shared data ensurance and data integrity will be checked. our wdgM will monitor Task and interrupt excute Time and times when ,monitored some error and the error had not recovery in some time wdgM will reset MCU | P25: - | Q25: SW Architecture and SW Safety Analysis | R25: X
A26: ISO26262-6.7_90(0) | B26: What are the mechanisms implemented for error detections at software architecture level? 1. Range checks of input and output data 2. Plausibility check 3. Detection of data errors 4. Monitoring of program execution by external element such as an ASIC or another software element performing a watchdog function 5. Temporal monitoring of program execution 6. Diverse redundancy in the software design 7. Access violation control mechanisms implemented in software or hardware 8. Others to be detailed ISO 26262-6:2018 - 7.4.12 | C26: FC | E26: B3 | H26: B3 | J26: The software will follow these: 1. Range checks of input and output data 2. Plausibility check 3. Detection of data errors 5. Temporal monitoring of program execution 4. the software will monitor the program execution by internal watchdog. 6. the software will detect error periodically and excute the safe action 7. Access violation control mechanisms implemented in software or hardware | P26: - | Q26: SW Architecture and SW Safety Analysis | R26: X
A27: ISO26262-6.7_100(0) | B27: What are the safety mechanisms for handling error at software architecture level? 1. Deactivation in order to achieving and maintaining of a safe state 2. Static recovery mechanism 3. Graceful degradation 4. Homogenous redundancy in the design 5. Diverse redundancy in the design 6. Correcting codes for data 7. Access permission management implemented in software or hardware 8. Others to be detailed ISO 26262-6:2018 - 7.4.12 | C27: FC | E27: B3 | H27: B3 | J27: The software will follow these: 1. Deactivation in order to achieving and maintaining of a safe state 2. Static recovery mechanism 3. Graceful degradation 6. Correcting codes for data 4.5. the software will detect error periodically and excute the safe action (No need redundancy in this project) 7. Software partition management realizes the management of access rights. | P27: - | Q27: SW Architecture and SW Safety Analysis | R27: X
A28: ISO26262-6.7_110(0) | B28: Are resources estimated and which one? ISO 26262-6:2018 - 7.4.13 | C28: FC | E28: B2 | H28: B2 | J28: EEROM and RAM will be estimated in software design, CPU Loading utilization pencentage, estimation Information can be found in TDR. | P28: - | Q28: SW Architecture and SW Safety Analysis
A29: ISO26262-6.7_120(0) | B29: What are the principles for the verification of the software architectural design that are fulfilled in Table 4 and how are they fulfilled? ISO 26262-6:2018 - 7.4.14 | C29: FC | E29: B3 | H29: B3 | J29: TianMa product will follow: 1a Walk-through of the design 1b Inspection of the design 1c Simulation of dynamic behaviour of the design 1f Control flow analysis 1g Data flow analysis 1h Scheduling analysis | P29: - | Q29: SW Architecture and SW Safety Analysis
A30: Software unit design and implementation
A31: ISO26262-6.8_10(0) | B31: What is the notation to describe software unit design? ISO 26262-6:2018 - 8.4.3 | C31: FC | E31: B3 | H31: B3 | J31: TianMa product will follow: 1a Natural language 1b Informal natations (UML + data flow chart+words documents) | L31: NA | M31: NA | P31: - | Q31: SW Unit Design and Verification (incl. static analyses)
A32: ISO26262-6.8_20(0) | B32: What is the level of description in the specification of the software units? ISO 26262-6:2018 - 8.4.4 | C32: FC | E32: B3 | H32: B3 | J32: function behaviour and input output parameter get defined | P32: - | Q32: SW Unit Design and Verification (incl. static analyses)
A33: ISO26262-6.8_30(0) | B33: What are the design principles for software unit design and implementation in Table 6 that are fulfilled and how are they fulfilled? ISO 26262-6:2018 - 8.4.5 | C33: FC | E33: B3 | H33: B3 | J33: TianMa product will follow: 1a One entry and one exit point in subprograms and functions 1b No dynamic objects or variables, or else online test during their creation 1c Initialization of variables 1d No multiple use of variable names 1f Restricted use of pointers 1g No implicit type conversions 1h No hidden data flow or control flow 1i No unconditional jumps | P33: - | Q33: SW Unit Design and Verification (incl. static analyses)
A34: Software unit verification
A35: ISO26262-6.9_10(0) | B35: What are the methods for software unit verification in Table 7 that are fulfilled and how are they fulfilled? ISO 26262-6:2018 - 9.4.2 | C35: FC | E35: B3 | H35: B3 | J35: TianMa product will follow: 1c Inspection 1h Static code analysis 1j Requirements-based test 1k Interface test | N35: Note: it should be aligned with answer to REGLESSW-ST-14-002(2) in sheet "Answer to STLA SW Dev. Rules" | P35: - | Q35: SW Unit Design and Verification (incl. static analyses) (1a to 1i) SW Unit test (1j to 1n) | R35: X
A36: ISO26262-6.9_30(0) | B36: What are the methods for deriving test cases for software unit testing (Table 8)? ISO 26262-6:2018 - 9.4.3 | C36: FC | E36: B3 | H36: B3 | J36: TianMa product will follow: 1a Analysis of requirements 1b Generation and analysis of equivalence classes 1c Analysis of boundary values | P36: - | Q36: SW Unit test
A37: ISO26262-6.9_40(0) | B37: What is the structural coverage target (Table 9)? ISO 26262-6:2018 - 9.4.4 | C37: FC | E37: B3 | H37: B3 | J37: TianMa product will follow: 1a Statement coverage 1b Branch coverage | P37: - | Q37: SW Unit test | R37: X
A38: ISO26262-6.9_50(0) | B38: What is the test environment for software unit testing? ISO 26262-6:2018 - 9.4.5 | C38: FC | E38: B3 | H38: B3 | J38: VectorCAST will be used | L38: NA | M38: NA | P38: - | Q38: SW Unit test
A39: Software integration and verification
A40: ISO26262-6.10_10(0) | B40: What is the strategy applied for software integration? ISO 26262-6:2018 - 10.4.1 | C40: FC | E40: B2 | H40: B2 | J40: Software integration stategy will be defined in SW integration test plan. bottom-up intergration stragegy and HW-SW intergtation | P40: - | Q40: SW Integration tests
...

Sheet WP Mapping
A1: DMOV
A2: Number | B2: ISO26262 SW Work products | C2: Supplier
C3: Corresponding document names | D3: Comments
B4: DIA
B5: Put here the DIA reference | C5: 02016_13_02411_Template_DIA_ISO26262_V6.2-0_Supplier
A6: 6-5 | B6: Initiation of product development at the software level
A7: 6-5.5.1 | B7: Documentation of the software development environment | C7: PDTM-G-WI13015 attachment 2 SW_SDP.docx | D7: Note that safety plan and verification plan are still mandatory. In the 2018 revision it was concentrated on part 2, requirement 6.4.6.5.So, please document the line below regarding planning of all safety related activities for the software development.
A8: 2-6.5.3 | B8: Safety plan | C8: PDTM-G-WI13019 attachment 2 Safety Plan.docx
A9: 6-6 | B9: Specification of software safety requirements
A10: 6-6.5.1 | B10: Software safety requirements specification | C10: PPDTM-G-WI13015 attachment 3 SW_SRS.docx
A11: 6-6.5.2 | B11: Hardware-software interface (HSI) specification (refined) | C11: PDTM-G-FM1301602 EE_HSIS.xlsx
A12: 6-6.5.3 | B12: Software verification report | C12: PDTM-G-FM1301501 SW_SRS_Review_Checklist.xlsx
A13: 6-7 | B13: Software architectural design
A14: 6-7.5.1 | B14: Software architectural design specification | C14: PDTM-G-WI13015 attachment 4 SW_SAS.docx
A15: 6-7.5.2 | B15: Safety analysis report | C15: PDTM-G-FM1301516 SW_DFMEA.xlsx
A16: 6-7.5.3 | B16: Dependent failures analysis report | C16: PDTM-G-FM1301517 Software Dependent Failure Analysis.xlsx
A17: 6-7.5.4 | B17: Software verification report | C17: PDTM-G-FM1301502 SW_SAS_Review_Checklist.xlsx
A18: 6-8 | B18: Software unit design and implementation
A19: 6-8.5.1 | B19: Software unit design specification | C19: PDTM-G-WI13015 attachment 5 SW_SDD.docx
A20: 6-8.5.2 | B20: Software unit implementation | C20: SW_Source Code
A21: 6-9 | B21: Software unit testing
A22: 6-9.5.1 | B22: Software verification specification | C22: PDTM-G-WI13015 attachment 6 SW_Unit Verification Plan.docx
A23: 6-9.5.2 | B23: Software verification report (refined) | C23: PDTM-G-FM1301509 SW_Unit Verification Report.xlsx
A24: 6-10 | B24: Software integration and testing
A25: 6-10.5.1 | B25: Software verification specification (refined) | C25: PDTM-G-WI13015 attachment 7 SW_Integration Test Plan.docx
A26: 6-10.5.2 | B26: Embedded software | C26: PDTM-G-FM1301512 SW_Integration Test Case.xlsx
A27: 6-10.5.3 | B27: Software verification report (refined) | C27: PDTM-G-FM1301514 SW_Integration Test Report.xlsx
A28: 6-11 | B28: Verification of software safety requirements
A29: 6-11.5.1 | B29: Software verification specification (refined) | C29: PDTM-G-WI13014 attachment 4 SW_Qualification Test Plan.docx
A30: 6-11.5.2 | B30: Software verification report (refined) | C30: PDTM-G-FM1301417 SW Qualification Test Report.xlsx
A31: 6-C | B31: Software configuration requirements
A32: 6-C.5.1 | B32: Configuration data specification | C32: PDTM-G-FM1301518 SW Configuration and Calibration data.xlsx
A33: 6-C.5.2 | B33: Calibration data specification
A34: 6-C.5.3 | B34: Configuration data
A35: 6-C.5.4 | B35: Calibration data
A36: 6-C.5.5 | B36: Verification specification (refined) | C36: PDTM-G-WI13014 attachment 4 SW_Qualification Test Plan.docx
A37: 6-C.5.6 | B37: Verification report (refined) | C37: PDTM-G-FM1301417 SW Qualification Test Report.xlsx
A38: 6-C.5.7 | B38: Software architectural design specification (refined) | C38: PDTM-G-WI13015 attachment 4 SW_SAS.docx
A39: 6-C.5.8 | B39: Documentation of the software development environment (refined) | C39: PDTM-G-WI13015 attachment 2 SW_SDP.docx
A40: 8-11 | B40: Confidence in the use of software tools
...

Sheet Answer to security rules
A1: DMOV
A2: Requirement | B2: Description | C2: Supplier answer | K2: STLA review status
C3: Conformity Status | D3: Implementation Status | E3: Implementation delivery (planned) | F3: Implementation delivery (real) | G3: Verification & Validation Status | H3: Verification & Validation delivery (planned) | I3: Verification & Validation delivery (real) | J3: Justification/Answer | K3: Conformity Status | L3: Implementation Status | M3: Verification & Validation Status | N3: Remark | O3: Documents or Meeting Minutes References | P3: Action Plan
A4: 02016_17_06732_110(0) | B4: The microcontroller debug ports shall be disabled for serial electronic control unit before serial life (fused or secured). | C4: FC | P4: - | S4: NA | T4: Not Applicable | U4: =COUNTIF(C$4:C$29,"NA") -> 0 | X4: OK | Y4: =COUNTIF(K$4:K$29,"OK") -> 0 | AA4: OK | AB4: OK | AC4: =COUNTIF(K$4:K$134,"OK") -> 0 | AE4: Action Plan :
A5: 02016_17_06732_120(0) | B5: The diagnostic protocol supplier's session is allowed to do physical addressing but the entry in this session shall be secured by a state-of-the-art cryptographic mechanism. The cryptographic mechanism will have to be communicated to STLA via a detailed document for approval. | C5: FC | P5: - | S5: NC | T5: No compliant | U5: =COUNTIF(C$4:C$29,"NC") -> 0 | X5: NOK | Y5: =COUNTIF(K$4:K$29,"NOK") -> 0 | AA5: NOK | AB5: NOK | AC5: =COUNTIF(K$4:K$134,"NOK") -> 0 | AE5: -
A6: 02016_17_06732_130(0) | B6: The diagnostic protocol supplier's session is not allowed to upload software (from electronic control unit to a tool) on serial life. | C6: FC | P6: - | S6: PC | T6: Partly compliant | U6: =COUNTIF(C$4:C$29,"PC") -> 0 | X6: NA | Y6: =COUNTIF(K$4:K$29,"NA") -> 0 | AA6: TBA | AB6: To Be Assessed | AC6: =COUNTIF(K$4:K$134,"TBA") -> 0 | AE6: ongoing
A7: 02016_17_06732_140(0) | B7: Supplier's diagnosis requests shall be made known to STLA via a detailed document for approval. | C7: FC | P7: - | S7: LC | T7: Largely compliant | U7: =COUNTIF(C$4:C$29,"LC") -> 0 | AA7: NA | AB7: Not Applicable | AC7: =COUNTIF(K$4:K$134,"NA") -> 0 | AE7: closed
A8: 02016_17_06732_150(0) | B8: The writing rights of mechanisms for development electronic control unit protocols (XCP protocol for example) shall be irreversibly deleted before serial life. | C8: FC | P8: - | S8: FC | T8: Fully compliant | U8: =COUNTIF(C$4:C$29,"FC") -> 8
A9: 02016_17_06732_160(0) | B9: The reading rights of mechanisms for development electronic control unit protocols shall be irreversibly deleted on stack, Heap, Flash code before serial life. | C9: FC | P9: -
A10: 02016_17_06732_170(0) | B10: Functional message identifiers shall not be in STLA's calibration or supplier's calibration. They shall be hard coded. | C10: FC | P10: -
A11: 02016_17_06732_180(0) | B11: The configuration data (microcontroller, bootloader, application) shall not be located in external nonvolatile memory. If not, a fully list of these configuration data will have to be communicated to STLA via a detailed document for approval. | C11: FC | P11: -
A12: To add a new question, insert new line above, to not suppress line. | P12: -

Sheet Software Checklist
A1: DMOV
A2: Identifier | B2: Check | C2: Supplier answer | E2: STLA review status
C3: Response | D3: Justification / Comment | E3: Status | F3: Remark / Comment
A4: Block Diagram (SWE.2: BP1,BP6)
A5: DMOV_SW_Checklist_00010 | B5: High level block diagram for software architecture is available | C5: YES | D5: Refer software architecture design document
A6: DMOV_SW_Checklist_00020 | B6: Software Architecture Structure is shown clearly with all hierarchical levels and components of each level. | C6: YES | D6: Refer software architecture design document
A7: DMOV_SW_Checklist_00030 | B7: The diagram Identifies ECU class, ASIL/QM components, secure components, legacy components etc. | C7: YES | D7: Refer software architecture design document
A8: DMOV_SW_Checklist_00040 | B8: In-house/STLA developed Components are identified | C8: YES | D8: All modules are developed by Tianma.
A9: DMOV_SW_Checklist_00050 | B9: COTS are identified | C9: YES
A10: DMOV_SW_Checklist_00060 | B10: Re-used Components are identified with reused version and estimate of reuse rate. | C10: NOT APPLICABLE | D10: No code reuse
A11: DMOV_SW_Checklist_00070 | B11: New Components are Identified | C11: YES | D11: New components marked in architecture design.
A12: Components Interface Documents(SWE.2:BP3,BP4,BP6)
A13: DMOV_SW_Checklist_00200 | B13: Interface document of each component is available | C13: YES | D13: Refer software interface document
A14: DMOV_SW_Checklist_00210 | B14: I/O (sender/receiver) and API (client/server) list for each component is available in the Interface document | C14: YES | D14: Refer software interface document
A15: DMOV_SW_Checklist_00220 | B15: Data types are defined for the I/O (sender/receiver) list and for API (client/server) list | C15: YES | D15: Refer software interface document
A16: DMOV_SW_Checklist_00230 | B16: Ranges/resolutions are defined for the I/O (sender/receiver) values and and API (client/server) parameter values | C16: YES | D16: Refer software interface document
A17: DMOV_SW_Checklist_00240 | B17: Source of Input is identified. (e.g. Component name, EEPROM, Parameter etc.) | C17: YES | D17: Refer software interface document
A18: DMOV_SW_Checklist_00250 | B18: Category of Input is identified (e.g. A/D, Signal value from RAM, CAN value etc.) | C18: YES | D18: Refer software interface document
A19: DMOV_SW_Checklist_00260 | B19: Category of Output is identified e.g. EEPROM, RAM, CAN | C19: YES | D19: Refer software interface document
A20: DMOV_SW_Checklist_00270 | B20: Function (runnable) periodicity is defined and justified in the interface document | C20: YES | D20: Refer software architecture design document
A21: Components Arch and Traceability(SWE.2: BP2,BP6,BP7,BP8)
A22: DMOV_SW_Checklist_00400 | B22: Baselined software requirements are allocated to components, and architecture design is available for each component and baselined | C22: YES
A23: DMOV_SW_Checklist_00410 | B23: Bi-directional traceability is established between components and baselined Requirements | C23: YES
A24: DMOV_SW_Checklist_00420 | B24: Complexity of Components is restricted and all components are evaluated for indicators of high complexity e.g. excessive number of requirements allocated, excessive number of global variables, difficult to achieve test coverage etc. And decisions made to stay within the restricted complexity range for components. | C24: YES | D24: The unit detailed design document reflects the complexity of the function and ensure testability
A25: Memory Resources(SWE.2: BP5,BP6)
A26: DMOV_SW_Checklist_00600 | B26: High Level Memory Map (e.g. application, bootloader, calibration, manufacturing data) for the software blocks | C26: YES
A27: DMOV_SW_Checklist_00610 | B27: The RAM/ROM/EEPROM budget is allocated to each component including bootloader if any. | C27: YES | D27: Refer software architecture design document
A28: DMOV_SW_Checklist_00620 | B28: Resource usage is followed and is not beyond the defined limit by STLA. If limits are not specified in ECU's specification, refer to tables in DMOV_SW_Checklist_05200 or DMOV_SW_Checklist_05210. | C28: YES
A29: CPU Resources(SWE.2: BP5,BP6)
A30: DMOV_SW_Checklist_00800 | B30: The CPU budget is allocated to each component/function and interrupts | C30: YES | D30: Refer software architecture design document
A31: DMOV_SW_Checklist_00810 | B31: CPU load is followed and is not beyond the defined limit specified by STLA. If limits are not specified in ECU's specification, refer to tables in DMOV_SW_Checklist_05200 or DMOV_SW_Checklist_05210. | C31: YES
A32: OS/Scheduler(SWE.2: BP4,BP6)
A33: DMOV_SW_Checklist_01000 | B33: Details of the OS design chosen is documented and justified. (e.g. Scheduler, Pre-emptive/Non Pre-emptive OS) | C33: YES | D33: Fellow Flexible Safety RTOS guideline, architecture document show OS design.
A34: DMOV_SW_Checklist_01010 | B34: Details of Interrupts with the periodicity and priorities assigned are documented. | C34: YES | D34: Refer software architecture design document
A35: DMOV_SW_Checklist_01020 | B35: Strategies are considered for minimizing the interrupts and execution time. | C35: YES
A36: DMOV_SW_Checklist_01030 | B36: Details of tasks with the periodicity and priorities assigned is documented | C36: YES | D36: Refer software architecture design document
A37: DMOV_SW_Checklist_01035 | B37: Task multiple activation is documented and justified (ex : in AUTOSAR, value of OSTaskActivation parameter) | C37: NOT APPLICABLE | D37: Fsrtos does not support multiple activations of a task.
A38: DMOV_SW_Checklist_01040 | B38: Tick is documented and justified | C38: YES
A39: DMOV_SW_Checklist_01050 | B39: Deadlock management strategy is documented | C39: NOT APPLICABLE | D39: No use in this project. | F39: Note: it should be aligned with answer to REGLESSW-ST-11-004
A40: DMOV_SW_Checklist_01060 | B40: Execution overrun strategy is documented | C40: YES
...

Sheet LRM Checklist
A1: DMOV
A2: Reference | B2: Question | C2: Supplier answer | E2: STLA decision
C3: Conformity Status | D3: Justification/Answer | E3: Conformity Status | F3: Remark
A4: SL_SW_MOD_CL_10(0) | B4: As modifications done during production are even more critical than during development phase the whole defined and agreed process will have to be fully followed (e.g.: change management, configuration management, updated documentation and traceability, updated tests, tests results, delivery check, etc.) Typically, like for major releases, the full delivery shall be provided. | C4: FC | H4: NA | I4: Not Applicable | J4: =COUNTIF(C$4:C$29,"NA") -> 0 | L4: OK | M4: OK | N4: =COUNTIF(E$4:E$133,"OK") -> 0
A5: SL_SW_MOD_CL_20(0) | B5: Each modification done by the supplier shall be reviewed and agreed by STLA. During this review, for each modification, the supplier shall: - show any modified part (e.g. : source code, data files, configuration files, generation parameters, etc.) - demonstrate through an impact analysis that any effect or side effect of the modification has been identified and has been checked locally but also more globally (e.g. effects on scheduling, CPU load or System utilization, NVM usage and size and lifecycle, product lifecycle, WD strategy, etc.) | C5: FC | H5: NC | I5: No compliant | J5: =COUNTIF(C$4:C$29,"NC") -> 0 | L5: NOK | M5: NOK | N5: =COUNTIF(E$4:E$133,"NOK") -> 0
A6: SL_SW_MOD_CL_30(0) | B6: Risk Management Plan is updated and applied. | C6: FC | H6: PC | I6: Partly compliant | J6: =COUNTIF(C$4:C$29,"PC") -> 0 | L6: TBA | M6: To Be Assessed | N6: =COUNTIF(E$4:E$133,"TBA") -> 0
A7: SL_SW_MOD_CL_40(0) | B7: Impact analysis is done and all related files are updated (source code but also software specification and validation). | C7: FC | H7: LC | I7: Largely compliant | J7: =COUNTIF(C$4:C$29,"LC") -> 0 | L7: NA | M7: Not Applicable | N7: =COUNTIF(E$4:E$133,"NA") -> 0
A8: SL_SW_MOD_CL_50(0) | B8: Modifications are reviewed and non-conformities detected are fixed (source code but also software specification and validation). | C8: FC | H8: FC | I8: Fully compliant | J8: =COUNTIF(C$4:C$29,"FC") -> 12
A9: SL_SW_MOD_CL_60(0) | B9: A software configuration audit was performed which notably confirms that no other modification than planned with STLA was done. | C9: FC
A10: SL_SW_MOD_CL_70(0) | B10: Sheets of this document DMOV are updated and all changes sent to STLA for approval (examples: static analysis, warnings justification, code metrics, code review by microcontroller maker for low level software, ECC activation etc.) | C10: FC
A11: SL_SW_MOD_CL_80(0) | B11: Specification is up-to-date (especially: software requirement document, software architecture document and software design documents) | C11: FC
A12: SL_SW_MOD_CL_90(0) | B12: Traceability is up-to-date | C12: FC
A13: SL_SW_MOD_CL_95(0) | B13: Test strategy is based on impact analysis. Moreover, supplier shall also run a minimum set of tests, at least sanity checks, on safety, security and approval modules. | C13: FC
A14: SL_SW_MOD_CL_100(1) | B14: Test strategy applied to verify the changes was reviewed and approved by STLA. | C14: FC
A15: SL_SW_MOD_CL_110(0) | B15: Tests are up-to-date (especially unit tests, integration tests and software tests), according to the Test strategy reviewed with STLA. | C15: FC

Sheet DMOV Topics Classification
A1: DMOV Questions classification
C2: The questions in the DMOV are classified according to these topics, see last column in the DMOV checklists.
B3: Topic | C3: Contents | D3: Related review questions | G3: Related SW/ISO26262 workproducts
D4: SW Dev Rules | E4: ISO26262 | F4: Security
B5: General topics | C5: Selection criterias for design, modeling and coding languages Lessons Learned | D5: REGLESSW-ST-14-003 REGLESSW-ST-15-000 | E5: ISO26262-6.5_00 ISO26262-6.5_30 | G5: Part 6 - 5.5.1 Documentation of the software development environment
B6: Planification of SW Safety activities | E6: ISO26262-6.5_10 ISO26262-6.5_20 | G6: Part 6 - 6.5.3 Safety plan
B7: Software Safety requirements and traceability | C7: Requirements management, including HSI Upstream / downstream traceability From STLA TSR to Supplier TSR From STLA TSR to Supplier TSR Completness and maturity of requirements Examples of SSR ASIL rating | E7: ISO26262-6.6_10 ISO26262-6.6_20 ISO26262-6.6_30 ISO26262-6.6_40 ISO26262-6.6_50 | G7: Part 6 - 6.5.1 Software safety requirements specification Part 6 - 6.5.2 Hardware-software interface (HSI) specification (refined) Part 6 - 6.5.3 Software verification report
